Workbook

Sheet Actualización
B2: Datos de Actualización
G3: año actual: | H3: =YEAR(D5) -> 2026
C5: mes: | D5: 46023 | G5: mensuales: | J5: trimestrales: | N5: bimestrales: | R5: bimestrales: | U5: semestrales: | Y5: anual:
G6: =DATE(H3-1,1,1) -> 45658 | H6: Enero | J6: actual | K6: trim Anterior | L6: año anterior | N6: actual | O6: bim Anterior | P6: año anterior | R6: actual | S6: =+K6 -> trim Anterior | T6: año anterior | U6: actual | V6: sem Anterior | W6: año anterior | Y6: =$H$3-4 -> 2022
C7: bimestre natural: | D7: Noviembre-diciembre 2025 | G7: =EDATE(G6,1) -> 45689 | H7: Febrero | J7: =CONCATENATE($H$3-2,"-I") -> 2024-I | N7: =CONCATENATE("Enero-febrero ",$H$3-2) -> Enero-febrero 2024 | R7: =CONCATENATE("Enero-febrero ",$H$3-2) -> Enero-febrero 2024 | U7: =CONCATENATE("S I-",$H$3-3) -> S I-2023 | Y7: =$H$3-3 -> 2023
C8: Trimestre Adelantado: | D8: Octubre-Noviembre 2025 | G8: =EDATE(G7,1) -> 45717 | H8: Marzo | J8: =CONCATENATE($H$3-2,"-II") -> 2024-II | K8: =J7 -> 2024-I | N8: =CONCATENATE("Marzo-abril ",$H$3-2) -> Marzo-abril 2024 | O8: =N7 -> Enero-febrero 2024 | R8: =CONCATENATE("Abril-mayo ",$H$3-2) -> Abril-mayo 2024 | S8: =+J7 -> 2024-I | U8: =CONCATENATE("S II-",$H$3-3) -> S II-2023 | V8: =U7 -> S I-2023 | Y8: =$H$3-2 -> 2024
G9: =EDATE(G8,1) -> 45748 | H9: Abril | J9: =CONCATENATE($H$3-2,"-III") -> 2024-III | K9: =J8 -> 2024-II | N9: =CONCATENATE("Mayo-junio ",$H$3-2) -> Mayo-junio 2024 | O9: =N8 -> Marzo-abril 2024 | R9: =CONCATENATE("Julio-agosto ",$H$3-2) -> Julio-agosto 2024 | S9: =+J8 -> 2024-II | U9: =CONCATENATE("S I-",$H$3-2) -> S I-2024 | V9: =U8 -> S II-2023 | W9: =U7 -> S I-2023 | Y9: =$H$3-1 -> 2025
C10: trimestre: | D10: 2025-IV | G10: =EDATE(G9,1) -> 45778 | H10: Mayo | J10: =CONCATENATE($H$3-2,"-IV") -> 2024-IV | K10: =J9 -> 2024-III | N10: =CONCATENATE("Julio-agosto ",$H$3-2) -> Julio-agosto 2024 | O10: =N9 -> Mayo-junio 2024 | R10: =CONCATENATE("Octubre-Noviembre ",$H$3-2) -> Octubre-Noviembre 2024 | S10: =+J9 -> 2024-III | U10: =CONCATENATE("S II-",$H$3-2) -> S II-2024 | V10: =U9 -> S I-2024 | W10: =U8 -> S II-2023 | Y10: =$H$3 -> 2026
G11: =EDATE(G10,1) -> 45809 | H11: Junio | J11: =CONCATENATE($H$3-1,"-I") -> 2025-I | K11: =J10 -> 2024-IV | L11: =J7 -> 2024-I | N11: =CONCATENATE("Septiembre-octubre ",$H$3-2) -> Septiembre-octubre 2024 | O11: =N10 -> Julio-agosto 2024 | R11: =CONCATENATE("Enero-febrero ",$H$3-1) -> Enero-febrero 2025 | S11: =+J10 -> 2024-IV | T11: =+J7 -> 2024-I | U11: =CONCATENATE("S I-",$H$3-1) -> S I-2025 | V11: =U10 -> S II-2024 | W11: =U9 -> S I-2024
C12: semestre: | D12: S II-2025 | G12: =EDATE(G11,1) -> 45839 | H12: Julio | J12: =CONCATENATE($H$3-1,"-II") -> 2025-II | K12: =J11 -> 2025-I | L12: =J8 -> 2024-II | N12: =CONCATENATE("Noviembre-diciembre ",$H$3-2) -> Noviembre-diciembre 2024 | O12: =N11 -> Septiembre-octubre 2024 | R12: =CONCATENATE("Abril-mayo ",$H$3-1) -> Abril-mayo 2025 | S12: =+J11 -> 2025-I | T12: =+J8 -> 2024-II | U12: =CONCATENATE("S II-",$H$3-1) -> S II-2025 | V12: =U11 -> S I-2025 | W12: =U10 -> S II-2024
G13: =EDATE(G12,1) -> 45870 | H13: Agosto | J13: =CONCATENATE($H$3-1,"-III") -> 2025-III | K13: =J12 -> 2025-II | L13: =J9 -> 2024-III | N13: =CONCATENATE("Enero-febrero ",$H$3-1) -> Enero-febrero 2025 | O13: =N12 -> Noviembre-diciembre 2024 | P13: =N7 -> Enero-febrero 2024 | R13: =CONCATENATE("Julio-agosto ",$H$3-1) -> Julio-agosto 2025 | S13: =+J12 -> 2025-II | T13: =+J9 -> 2024-III | U13: =CONCATENATE("S I-",$H$3) -> S I-2026 | V13: =U12 -> S II-2025 | W13: =U11 -> S I-2025
C14: año: | D14: 2025 | G14: =EDATE(G13,1) -> 45901 | H14: Septiembre | J14: =CONCATENATE($H$3-1,"-IV") -> 2025-IV | K14: =J13 -> 2025-III | L14: =J10 -> 2024-IV | N14: =CONCATENATE("Marzo-abril ",$H$3-1) -> Marzo-abril 2025 | O14: =N13 -> Enero-febrero 2025 | P14: =N8 -> Marzo-abril 2024 | R14: =CONCATENATE("Octubre-Noviembre ",$H$3-1) -> Octubre-Noviembre 2025 | S14: =+J13 -> 2025-III | T14: =+J10 -> 2024-IV | U14: =CONCATENATE("S II-",$H$3) -> S II-2026 | V14: =U13 -> S I-2026 | W14: =U12 -> S II-2025
G15: =EDATE(G14,1) -> 45931 | H15: Octubre | J15: =CONCATENATE($H$3,"-I") -> 2026-I | K15: =J14 -> 2025-IV | L15: =J11 -> 2025-I | N15: =CONCATENATE("Mayo-junio ",$H$3-1) -> Mayo-junio 2025 | O15: =N14 -> Marzo-abril 2025 | P15: =N9 -> Mayo-junio 2024 | R15: =CONCATENATE("Enero-febrero ",$H$3) -> Enero-febrero 2026 | S15: =+J14 -> 2025-IV | T15: =+J11 -> 2025-I
G16: =EDATE(G15,1) -> 45962 | H16: Noviembre | J16: =CONCATENATE($H$3,"-II") -> 2026-II | K16: =J15 -> 2026-I | L16: =J12 -> 2025-II | N16: =CONCATENATE("Julio-agosto ",$H$3-1) -> Julio-agosto 2025 | O16: =N15 -> Mayo-junio 2025 | P16: =N10 -> Julio-agosto 2024 | R16: =CONCATENATE("Abril-mayo ",$H$3) -> Abril-mayo 2026 | S16: =+J15 -> 2026-I | T16: =+J12 -> 2025-II
G17: =EDATE(G16,1) -> 45992 | H17: Diciembre | J17: =CONCATENATE($H$3,"-III") -> 2026-III | K17: =J16 -> 2026-II | L17: =J13 -> 2025-III | N17: =CONCATENATE("Septiembre-octubre ",$H$3-1) -> Septiembre-octubre 2025 | O17: =N16 -> Julio-agosto 2025 | P17: =N11 -> Septiembre-octubre 2024 | R17: =CONCATENATE("Julio-agosto ",$H$3) -> Julio-agosto 2026 | S17: =+J16 -> 2026-II | T17: =+J13 -> 2025-III
G18: =EDATE(G17,1) -> 46023 | H18: Enero | J18: =CONCATENATE($H$3,"-IV") -> 2026-IV | K18: =J17 -> 2026-III | L18: =J14 -> 2025-IV | N18: =CONCATENATE("Noviembre-diciembre ",$H$3-1) -> Noviembre-diciembre 2025 | O18: =N17 -> Septiembre-octubre 2025 | P18: =N12 -> Noviembre-diciembre 2024 | R18: =CONCATENATE("Octubre-Noviembre ",$H$3) -> Octubre-Noviembre 2026 | S18: =+J17 -> 2026-III | T18: =+J14 -> 2025-IV
G19: =EDATE(G18,1) -> 46054 | H19: Febrero | N19: =CONCATENATE("Enero-febrero ",$H$3) -> Enero-febrero 2026 | O19: =N18 -> Noviembre-diciembre 2025 | P19: =N13 -> Enero-febrero 2025
G20: =EDATE(G19,1) -> 46082 | H20: Marzo | N20: =CONCATENATE("Marzo-abril ",$H$3) -> Marzo-abril 2026 | O20: =N19 -> Enero-febrero 2026 | P20: =N14 -> Marzo-abril 2025
G21: =EDATE(G20,1) -> 46113 | H21: Abril | N21: =CONCATENATE("Mayo-junio ",$H$3) -> Mayo-junio 2026 | O21: =N20 -> Marzo-abril 2026 | P21: =N15 -> Mayo-junio 2025
G22: =EDATE(G21,1) -> 46143 | H22: Mayo | N22: =CONCATENATE("Julio-agosto ",$H$3) -> Julio-agosto 2026 | O22: =N21 -> Mayo-junio 2026 | P22: =N16 -> Julio-agosto 2025
G23: =EDATE(G22,1) -> 46174 | H23: Junio | N23: =CONCATENATE("Septiembre-octubre ",$H$3) -> Septiembre-octubre 2026 | O23: =N22 -> Julio-agosto 2026 | P23: =N17 -> Septiembre-octubre 2025
G24: =EDATE(G23,1) -> 46204 | H24: Julio | N24: =CONCATENATE("Noviembre-diciembre ",$H$3) -> Noviembre-diciembre 2026 | O24: =N23 -> Septiembre-octubre 2026 | P24: =N18 -> Noviembre-diciembre 2025
G25: =EDATE(G24,1) -> 46235 | H25: Agosto
G26: =EDATE(G25,1) -> 46266 | H26: Septiembre
G27: =EDATE(G26,1) -> 46296 | H27: Octubre
G28: =EDATE(G27,1) -> 46327 | H28: Noviembre
G29: =EDATE(G28,1) -> 46357 | H29: Diciembre
G30: =EDATE(G29,1) -> 46388 | H30: Enero
G31: =EDATE(G30,1) -> 46419 | H31: Febrero
G32: =EDATE(G31,1) -> 46447 | H32: Marzo
G33: =EDATE(G32,1) -> 46478 | H33: Abril
G34: =EDATE(G33,1) -> 46508 | H34: Mayo
G35: =EDATE(G34,1) -> 46539 | H35: Junio
G36: =EDATE(G35,1) -> 46569 | H36: Julio
... G41: =EDATE(G40,1) -> 46722 | H41: Diciembre

Sheet Ponderadores
A1: PONDERADORES PIB 2018
B3: Total | C3: SIN AUTOS
A5: ACTIVIDAD INDUSTRIAL | B5: =+[1]Ponderadores!C5 -> 7747139.7 | C5: =C6+C10+C13+C17 -> 6578639
A6: Industria Minera | B6: =+[1]Ponderadores!C6 -> 948326.58 | C6: =SUM(C7:C9) -> 948326.58
A7: Extracción de petróleo y gas | B7: =+[1]Ponderadores!C7 -> 621540.6 | C7: =B7 -> 621540.6
A8: Minería de minerales metálicos y no metálicos excepto petróleo y gas, y servicios relacionados | B8: =+[1]Ponderadores!C8 -> 265067.55 | C8: =B8 -> 265067.55
A9: Servicios relacionados con la minería | B9: =+[1]Ponderadores!C9 -> 61718.433 | C9: =B9 -> 61718.433
A10: Electricidad, agua y suministro de gas por ductos al consumidor fina | B10: =+[1]Ponderadores!C10 -> 456907.22 | C10: =SUM(C11:C12) -> 456907.22
A11: Generación, transmisión y suministro de energía eléctrica | B11: =+[1]Ponderadores!C11 -> 456907.22 | C11: =B11 -> 456907.22
A12: Agua y suministro de gas por ductos al consumidor final | B12: =+[1]Ponderadores!C12 -> 0 | C12: =B12 -> 0
A13: Construcción | B13: =+[1]Ponderadores!C13 -> 1460789.5 | C13: =SUM(C14:C16) -> 1460789.5
A14: Edificación | B14: =+[1]Ponderadores!C14 -> 1064926.3 | C14: =B14 -> 1064926.3
A15: Construcción de obras de ingeniería civil u obra pesada | B15: =+[1]Ponderadores!C15 -> 214062.02 | C15: =B15 -> 214062.02
A16: Trabajos especializados para la construcción | B16: =+[1]Ponderadores!C16 -> 181801.25 | C16: =B16 -> 181801.25
A17: Total industrias manufactureras | B17: =+[1]Ponderadores!C17 -> 4881116.4 | C17: =SUM(C18:C38) -> 3712615.6
A18: Industria alimentaria | B18: =+[1]Ponderadores!C18 -> 911713.77 | C18: =B18 -> 911713.77
A19: Industria de las bebidas y del tabaco | B19: =+[1]Ponderadores!C19 -> 240174.37 | C19: =B19 -> 240174.37
A20: Fabricación de insumos textiles | B20: =+[1]Ponderadores!C20 -> 32513.579 | C20: =B20 -> 32513.579
A21: Confección de productos textiles, excepto prendas de vestir | B21: =+[1]Ponderadores!C21 -> 17328.629 | C21: =B21 -> 17328.629
A22: Fabricación de prendas de vestir | B22: =+[1]Ponderadores!C22 -> 71182.811 | C22: =B22 -> 71182.811
A23: Fabricación de productos de cuero, piel y materiales sucedáneos, excepto prendas de vestir | B23: =+[1]Ponderadores!C23 -> 31436.957 | C23: =B23 -> 31436.957
A24: Industria de la madera | B24: =+[1]Ponderadores!C24 -> 38837.812 | C24: =B24 -> 38837.812
A25: Industria del papel | B25: =+[1]Ponderadores!C25 -> 101611.97 | C25: =B25 -> 101611.97
A26: Impresión e industrias conexas | B26: =+[1]Ponderadores!C26 -> 24643.809 | C26: =B26 -> 24643.809
A27: Fabricación de productos derivados del petróleo y del carbón | B27: =+[1]Ponderadores!C27 -> 164436.95 | C27: =B27 -> 164436.95
A28: Industria química | B28: =+[1]Ponderadores!C28 -> 356405.6 | C28: =B28 -> 356405.6
A29: Industria del plástico y del hule | B29: =+[1]Ponderadores!C29 -> 151603.43 | C29: =B29 -> 151603.43
... A35: Fabricación de equipo de generación eléctrica y aparatos y accesorios eléctricos | B35: =+[1]Ponderadores!C35 -> 178614.04 | C35: =B35 -> 178614.04
A36: Fabricación de equipo de transporte | B36: =+[1]Ponderadores!C36 -> 1168500.8 | C36: 0
A37: Fabricación de muebles y productos relacionados | B37: =+[1]Ponderadores!C37 -> 55539.633 | C37: =B37 -> 55539.633
A38: Otras industrias manufactureras | B38: =+[1]Ponderadores!C38 -> 132857.27 | C38: =B38 -> 132857.27

Sheet DatosOri
B1: ACTIVIDAD INDUSTRIAL | C1: Industria Minera | D1: Extracción de petróleo y gas | E1: Minería de minerales metálicos y no metálicos excepto petróleo y gas, y servicios relacionados | F1: Servicios relacionados con la minería | G1: Electricidad, agua y suministro de gas por ductos al consumidor fina | H1: Generación, transmisión y suministro de energía eléctrica | I1: Construcción | J1: Edificación | K1: Construcción de obras de ingeniería civil u obra pesada | L1: Trabajos especializados para la construcción | M1: Total industrias manufactureras | N1: Industria alimentaria | O1: Industria de las bebidas y del tabaco | P1: Fabricación de insumos textiles | Q1: Confección de productos textiles, excepto prendas de vestir | R1: Fabricación de prendas de vestir | S1: Fabricación de productos de cuero, piel y materiales sucedáneos, excepto prendas de vestir | T1: Industria de la madera | U1: Industria del papel | V1: Impresión e industrias conexas | W1: Fabricación de productos derivados del petróleo y del carbón | X1: Industria química | Y1: Industria del plástico y del hule | Z1: Fabricación de productos a base de minerales no metálicos | AA1: Industrias metálicas básicas | AB1: Fabricación de productos metálicos | AC1: Fabricación de maquinaria y equipo | AD1: Fabricación de equipo de computación, comunicación, medición y otros equipos, componentes y accesorios electrónicos | AE1: Fabricación de equipo de generación eléctrica y aparatos y accesorios eléctricos | AF1: Fabricación de equipo de transporte | AG1: Fabricación de muebles y productos relacionados | AH1: Otras industrias manufactureras | AI1: Manufacturas sin equipo de transporte
A2: 41275 | B2: =[2]datos!C244 -> 91.795723 | C2: =[2]datos!F244 -> 131.03121 | D2: =[2]datos!I244 -> 146.19492 | E2: =[2]datos!L244 -> 102.43443 | F2: =[2]datos!O244 -> 101.14098 | G2: =[2]datos!R244 -> 83.150627 | H2: =[2]datos!U244 -> 83.150627 | I2: =[2]datos!AA244 -> 86.606116 | J2: =[2]datos!AD244 -> 81.275283 | K2: =[2]datos!AG244 -> 126.51361 | L2: =[2]datos!AJ244 -> 70.84311 | M2: =[2]datos!AM244 -> 86.535219 | N2: =[2]datos!AP244 -> 92.595093 | O2: =[2]datos!AS244 -> 74.599987 | P2: =[2]datos!AV244 -> 91.391605 | Q2: =[2]datos!AY244 -> 77.216511 | R2: =[2]datos!BB244 -> 80.603364 | S2: =[2]datos!BE244 -> 100.61752 | T2: =[2]datos!BH244 -> 90.440143 | U2: =[2]datos!BK244 -> 81.977775 | V2: =[2]datos!BN244 -> 71.950111 | W2: =[2]datos!BQ244 -> 194.20037 | X2: =[2]datos!BT244 -> 101.76442 | Y2: =[2]datos!BW244 -> 82.2275 | Z2: =[2]datos!BZ244 -> 84.997456 | AA2: =[2]datos!CC244 -> 96.938304 | AB2: =[2]datos!CF244 -> 91.911326 | AC2: =[2]datos!CI244 -> 93.430034 | AD2: =[2]datos!CL244 -> 70.265561 | AE2: =[2]datos!CO244 -> 100.07644 | AF2: =[2]datos!CR244 -> 66.904777 | AG2: =[2]datos!CU244 -> 86.741076 | AH2: =[2]datos!CX244 -> 70.670338 | AI2: =[3]Datos!D244 -> 92.713662
A3: 41306 | B3: =[2]datos!C245 -> 90.795957 | C3: =[2]datos!F245 -> 121.39022 | D3: =[2]datos!I245 -> 131.35293 | E3: =[2]datos!L245 -> 98.436452 | F3: =[2]datos!O245 -> 119.64152 | G3: =[2]datos!R245 -> 80.252433 | H3: =[2]datos!U245 -> 80.252433 | I3: =[2]datos!AA245 -> 94.162325 | J3: =[2]datos!AD245 -> 93.879487 | K3: =[2]datos!AG245 -> 118.42818 | L3: =[2]datos!AJ245 -> 67.247236 | M3: =[2]datos!AM245 -> 84.831441 | N3: =[2]datos!AP245 -> 90.278462 | O3: =[2]datos!AS245 -> 72.448995 | P3: =[2]datos!AV245 -> 94.141938 | Q3: =[2]datos!AY245 -> 84.400199 | R3: =[2]datos!BB245 -> 86.179975 | S3: =[2]datos!BE245 -> 99.554232 | T3: =[2]datos!BH245 -> 93.577037 | U3: =[2]datos!BK245 -> 77.965734 | V3: =[2]datos!BN245 -> 79.2707 | W3: =[2]datos!BQ245 -> 176.81715 | X3: =[2]datos!BT245 -> 96.041586 | Y3: =[2]datos!BW245 -> 81.392455 | Z3: =[2]datos!BZ245 -> 83.346652 | AA3: =[2]datos!CC245 -> 95.045485 | AB3: =[2]datos!CF245 -> 89.851684 | AC3: =[2]datos!CI245 -> 92.229002 | AD3: =[2]datos!CL245 -> 68.231782 | AE3: =[2]datos!CO245 -> 99.377454 | AF3: =[2]datos!CR245 -> 68.183794 | AG3: =[2]datos!CU245 -> 83.735858 | AH3: =[2]datos!CX245 -> 69.498124 | AI3: =[3]Datos!D245 -> 90.071086
A4: 41334 | B4: =[2]datos!C246 -> 92.46148 | C4: =[2]datos!F246 -> 131.90808 | D4: =[2]datos!I246 -> 143.33694 | E4: =[2]datos!L246 -> 102.58752 | F4: =[2]datos!O246 -> 142.73832 | G4: =[2]datos!R246 -> 82.735247 | H4: =[2]datos!U246 -> 82.735247 | I4: =[2]datos!AA246 -> 87.044218 | J4: =[2]datos!AD246 -> 83.592658 | K4: =[2]datos!AG246 -> 118.07519 | L4: =[2]datos!AJ246 -> 70.724775 | M4: =[2]datos!AM246 -> 87.329295 | N4: =[2]datos!AP246 -> 92.45331 | O4: =[2]datos!AS246 -> 80.047465 | P4: =[2]datos!AV246 -> 91.892847 | Q4: =[2]datos!AY246 -> 81.825591 | R4: =[2]datos!BB246 -> 85.600122 | S4: =[2]datos!BE246 -> 103.65714 | T4: =[2]datos!BH246 -> 102.93573 | U4: =[2]datos!BK246 -> 82.262866 | V4: =[2]datos!BN246 -> 84.383526 | W4: =[2]datos!BQ246 -> 195.47079 | X4: =[2]datos!BT246 -> 102.31779 | Y4: =[2]datos!BW246 -> 82.560939 | Z4: =[2]datos!BZ246 -> 86.497308 | AA4: =[2]datos!CC246 -> 102.04833 | AB4: =[2]datos!CF246 -> 91.435871 | AC4: =[2]datos!CI246 -> 90.231524 | AD4: =[2]datos!CL246 -> 68.489418 | AE4: =[2]datos!CO246 -> 90.556187 | AF4: =[2]datos!CR246 -> 69.030884 | AG4: =[2]datos!CU246 -> 83.863185 | AH4: =[2]datos!CX246 -> 71.973344 | AI4: =[3]Datos!D246 -> 93.088498
A5: 41365 | B5: =[2]datos!C247 -> 95.217513 | C5: =[2]datos!F247 -> 128.03237 | D5: =[2]datos!I247 -> 138.38781 | E5: =[2]datos!L247 -> 101.74208 | F5: =[2]datos!O247 -> 136.65822 | G5: =[2]datos!R247 -> 85.399436 | H5: =[2]datos!U247 -> 85.399436 | I5: =[2]datos!AA247 -> 91.490406 | J5: =[2]datos!AD247 -> 88.610517 | K5: =[2]datos!AG247 -> 123.81905 | L5: =[2]datos!AJ247 -> 70.294376 | M5: =[2]datos!AM247 -> 90.876553 | N5: =[2]datos!AP247 -> 92.320233 | O5: =[2]datos!AS247 -> 85.40994 | P5: =[2]datos!AV247 -> 96.82572 | Q5: =[2]datos!AY247 -> 98.224748 | R5: =[2]datos!BB247 -> 91.608591 | S5: =[2]datos!BE247 -> 102.35642 | T5: =[2]datos!BH247 -> 104.87881 | U5: =[2]datos!BK247 -> 83.933788 | V5: =[2]datos!BN247 -> 87.945585 | W5: =[2]datos!BQ247 -> 203.28893 | X5: =[2]datos!BT247 -> 103.36564 | Y5: =[2]datos!BW247 -> 85.397701 | Z5: =[2]datos!BZ247 -> 89.235944 | AA5: =[2]datos!CC247 -> 101.07217 | AB5: =[2]datos!CF247 -> 97.572055 | AC5: =[2]datos!CI247 -> 96.204756 | AD5: =[2]datos!CL247 -> 71.973418 | AE5: =[2]datos!CO247 -> 108.64378 | AF5: =[2]datos!CR247 -> 73.014699 | AG5: =[2]datos!CU247 -> 94.107327 | AH5: =[2]datos!CX247 -> 76.025253 | AI5: =[3]Datos!D247 -> 96.498355
A6: 41395 | B6: =[2]datos!C248 -> 96.751212 | C6: =[2]datos!F248 -> 129.29213 | D6: =[2]datos!I248 -> 142.7035 | E6: =[2]datos!L248 -> 103.31478 | F6: =[2]datos!O248 -> 105.79898 | G6: =[2]datos!R248 -> 90.687446 | H6: =[2]datos!U248 -> 90.687446 | I6: =[2]datos!AA248 -> 96.070223 | J6: =[2]datos!AD248 -> 92.591263 | K6: =[2]datos!AG248 -> 132.18548 | L6: =[2]datos!AJ248 -> 73.924785 | M6: =[2]datos!AM248 -> 91.200421 | N6: =[2]datos!AP248 -> 90.369501 | O6: =[2]datos!AS248 -> 87.788275 | P6: =[2]datos!AV248 -> 92.577166 | Q6: =[2]datos!AY248 -> 96.694065 | R6: =[2]datos!BB248 -> 89.75507 | S6: =[2]datos!BE248 -> 105.89182 | T6: =[2]datos!BH248 -> 100.37526 | U6: =[2]datos!BK248 -> 81.626038 | V6: =[2]datos!BN248 -> 87.66081 | W6: =[2]datos!BQ248 -> 216.73648 | X6: =[2]datos!BT248 -> 107.64914 | Y6: =[2]datos!BW248 -> 87.315587 | Z6: =[2]datos!BZ248 -> 91.878286 | AA6: =[2]datos!CC248 -> 98.30259 | AB6: =[2]datos!CF248 -> 99.504939 | AC6: =[2]datos!CI248 -> 95.705225 | AD6: =[2]datos!CL248 -> 78.894839 | AE6: =[2]datos!CO248 -> 91.945496 | AF6: =[2]datos!CR248 -> 72.507385 | AG6: =[2]datos!CU248 -> 96.753214 | AH6: =[2]datos!CX248 -> 76.230568 | AI6: =[3]Datos!D248 -> 97.083827
A7: 41426 | B7: =[2]datos!C249 -> 93.300123 | C7: =[2]datos!F249 -> 126.35874 | D7: =[2]datos!I249 -> 138.61696 | E7: =[2]datos!L249 -> 97.461431 | F7: =[2]datos!O249 -> 127.01906 | G7: =[2]datos!R249 -> 91.924812 | H7: =[2]datos!U249 -> 91.924812 | I7: =[2]datos!AA249 -> 86.543008 | J7: =[2]datos!AD249 -> 79.169182 | K7: =[2]datos!AG249 -> 137.02436 | L7: =[2]datos!AJ249 -> 70.296919 | M7: =[2]datos!AM249 -> 89.028303 | N7: =[2]datos!AP249 -> 85.01728 | O7: =[2]datos!AS249 -> 83.97204 | P7: =[2]datos!AV249 -> 95.424174 | Q7: =[2]datos!AY249 -> 91.553951 | R7: =[2]datos!BB249 -> 91.480466 | S7: =[2]datos!BE249 -> 103.94763 | T7: =[2]datos!BH249 -> 110.48205 | U7: =[2]datos!BK249 -> 79.139922 | V7: =[2]datos!BN249 -> 88.864379 | W7: =[2]datos!BQ249 -> 204.52217 | X7: =[2]datos!BT249 -> 108.98601 | Y7: =[2]datos!BW249 -> 84.744132 | Z7: =[2]datos!BZ249 -> 89.205653 | AA7: =[2]datos!CC249 -> 93.112281 | AB7: =[2]datos!CF249 -> 95.085837 | AC7: =[2]datos!CI249 -> 89.262014 | AD7: =[2]datos!CL249 -> 76.833742 | AE7: =[2]datos!CO249 -> 85.402622 | AF7: =[2]datos!CR249 -> 74.582722 | AG7: =[2]datos!CU249 -> 88.016466 | AH7: =[2]datos!CX249 -> 82.326947 | AI7: =[3]Datos!D249 -> 93.574874
A8: 41456 | B8: =[2]datos!C250 -> 96.415834 | C8: =[2]datos!F250 -> 131.84997 | D8: =[2]datos!I250 -> 141.31628 | E8: =[2]datos!L250 -> 95.486071 | F8: =[2]datos!O250 -> 192.69389 | G8: =[2]datos!R250 -> 94.359289 | H8: =[2]datos!U250 -> 94.359289 | I8: =[2]datos!AA250 -> 93.846601 | J8: =[2]datos!AD250 -> 85.491504 | K8: =[2]datos!AG250 -> 153.42713 | L8: =[2]datos!AJ250 -> 72.634616 | M8: =[2]datos!AM250 -> 90.492933 | N8: =[2]datos!AP250 -> 87.174524 | O8: =[2]datos!AS250 -> 86.911028 | P8: =[2]datos!AV250 -> 98.46817 | Q8: =[2]datos!AY250 -> 94.079693 | R8: =[2]datos!BB250 -> 102.64 | S8: =[2]datos!BE250 -> 108.11858 | T8: =[2]datos!BH250 -> 100.94666 | U8: =[2]datos!BK250 -> 83.044323 | V8: =[2]datos!BN250 -> 85.927295 | W8: =[2]datos!BQ250 -> 201.10212 | X8: =[2]datos!BT250 -> 110.24177 | Y8: =[2]datos!BW250 -> 87.703461 | Z8: =[2]datos!BZ250 -> 90.946807 | AA8: =[2]datos!CC250 -> 99.869764 | AB8: =[2]datos!CF250 -> 96.435535 | AC8: =[2]datos!CI250 -> 98.863171 | AD8: =[2]datos!CL250 -> 75.076814 | AE8: =[2]datos!CO250 -> 95.463048 | AF8: =[2]datos!CR250 -> 73.457355 | AG8: =[2]datos!CU250 -> 89.534597 | AH8: =[2]datos!CX250 -> 74.986197 | AI8: =[3]Datos!D250 -> 95.854674
A9: 41487 | B9: =[2]datos!C251 -> 96.179258 | C9: =[2]datos!F251 -> 127.50701 | D9: =[2]datos!I251 -> 142.82885 | E9: =[2]datos!L251 -> 95.16551 | F9: =[2]datos!O251 -> 112.10708 | G9: =[2]datos!R251 -> 95.432006 | H9: =[2]datos!U251 -> 95.432006 | I9: =[2]datos!AA251 -> 92.797342 | J9: =[2]datos!AD251 -> 87.745813 | K9: =[2]datos!AG251 -> 135.02593 | L9: =[2]datos!AJ251 -> 72.665294 | M9: =[2]datos!AM251 -> 91.174819 | N9: =[2]datos!AP251 -> 88.625028 | O9: =[2]datos!AS251 -> 89.725693 | P9: =[2]datos!AV251 -> 99.364545 | Q9: =[2]datos!AY251 -> 98.576793 | R9: =[2]datos!BB251 -> 99.470153 | S9: =[2]datos!BE251 -> 103.91479 | T9: =[2]datos!BH251 -> 105.61718 | U9: =[2]datos!BK251 -> 82.131217 | V9: =[2]datos!BN251 -> 90.631987 | W9: =[2]datos!BQ251 -> 200.7937 | X9: =[2]datos!BT251 -> 108.80028 | Y9: =[2]datos!BW251 -> 84.893569 | Z9: =[2]datos!BZ251 -> 89.760124 | AA9: =[2]datos!CC251 -> 99.331529 | AB9: =[2]datos!CF251 -> 104.76658 | AC9: =[2]datos!CI251 -> 87.52812 | AD9: =[2]datos!CL251 -> 75.866406 | AE9: =[2]datos!CO251 -> 98.871573 | AF9: =[2]datos!CR251 -> 75.524959 | AG9: =[2]datos!CU251 -> 93.919962 | AH9: =[2]datos!CX251 -> 75.328311 | AI9: =[3]Datos!D251 -> 96.100423
A10: 41518 | B10: =[2]datos!C252 -> 93.224201 | C10: =[2]datos!F252 -> 124.19876 | D10: =[2]datos!I252 -> 138.81763 | E10: =[2]datos!L252 -> 91.67915 | F10: =[2]datos!O252 -> 116.64309 | G10: =[2]datos!R252 -> 92.297135 | H10: =[2]datos!U252 -> 92.297135 | I10: =[2]datos!AA252 -> 93.873942 | J10: =[2]datos!AD252 -> 88.538299 | K10: =[2]datos!AG252 -> 138.62956 | L10: =[2]datos!AJ252 -> 72.430674 | M10: =[2]datos!AM252 -> 87.098644 | N10: =[2]datos!AP252 -> 83.784427 | O10: =[2]datos!AS252 -> 77.203133 | P10: =[2]datos!AV252 -> 91.720656 | Q10: =[2]datos!AY252 -> 98.149838 | R10: =[2]datos!BB252 -> 98.707339 | S10: =[2]datos!BE252 -> 102.8683 | T10: =[2]datos!BH252 -> 82.388961 | U10: =[2]datos!BK252 -> 78.326668 | V10: =[2]datos!BN252 -> 95.044265 | W10: =[2]datos!BQ252 -> 177.82 | X10: =[2]datos!BT252 -> 101.4775 | Y10: =[2]datos!BW252 -> 81.693695 | Z10: =[2]datos!BZ252 -> 83.128756 | AA10: =[2]datos!CC252 -> 97.150255 | AB10: =[2]datos!CF252 -> 92.317419 | AC10: =[2]datos!CI252 -> 81.914364 | AD10: =[2]datos!CL252 -> 80.369697 | AE10: =[2]datos!CO252 -> 100.59786 | AF10: =[2]datos!CR252 -> 73.814885 | AG10: =[2]datos!CU252 -> 101.68906 | AH10: =[2]datos!CX252 -> 77.130676 | AI10: =[3]Datos!D252 -> 91.279547
A11: 41548 | B11: =[2]datos!C253 -> 99.128999 | C11: =[2]datos!F253 -> 129.32753 | D11: =[2]datos!I253 -> 144.31857 | E11: =[2]datos!L253 -> 96.432465 | F11: =[2]datos!O253 -> 119.63636 | G11: =[2]datos!R253 -> 91.687539 | H11: =[2]datos!U253 -> 91.687539 | I11: =[2]datos!AA253 -> 98.308705 | J11: =[2]datos!AD253 -> 89.884312 | K11: =[2]datos!AG253 -> 159.72816 | L11: =[2]datos!AJ253 -> 75.33738 | M11: =[2]datos!AM253 -> 94.20395 | N11: =[2]datos!AP253 -> 88.870941 | O11: =[2]datos!AS253 -> 85.974741 | P11: =[2]datos!AV253 -> 102.30836 | Q11: =[2]datos!AY253 -> 95.653733 | R11: =[2]datos!BB253 -> 108.48044 | S11: =[2]datos!BE253 -> 114.98169 | T11: =[2]datos!BH253 -> 105.56136 | U11: =[2]datos!BK253 -> 83.067061 | V11: =[2]datos!BN253 -> 87.166464 | W11: =[2]datos!BQ253 -> 188.87902 | X11: =[2]datos!BT253 -> 109.85809 | Y11: =[2]datos!BW253 -> 87.470696 | Z11: =[2]datos!BZ253 -> 90.835894 | AA11: =[2]datos!CC253 -> 101.93648 | AB11: =[2]datos!CF253 -> 100.71691 | AC11: =[2]datos!CI253 -> 90.571411 | AD11: =[2]datos!CL253 -> 85.200606 | AE11: =[2]datos!CO253 -> 98.058855 | AF11: =[2]datos!CR253 -> 83.614522 | AG11: =[2]datos!CU253 -> 108.27399 | AH11: =[2]datos!CX253 -> 82.123207 | AI11: =[3]Datos!D253 -> 97.536844
A12: 41579 | B12: =[2]datos!C254 -> 95.100226 | C12: =[2]datos!F254 -> 127.40014 | D12: =[2]datos!I254 -> 138.26171 | E12: =[2]datos!L254 -> 100.33783 | F12: =[2]datos!O254 -> 134.2447 | G12: =[2]datos!R254 -> 86.993149 | H12: =[2]datos!U254 -> 86.993149 | I12: =[2]datos!AA254 -> 98.61829 | J12: =[2]datos!AD254 -> 89.588431 | K12: =[2]datos!AG254 -> 164.57557 | L12: =[2]datos!AJ254 -> 73.850496 | M12: =[2]datos!AM254 -> 88.530861 | N12: =[2]datos!AP254 -> 90.957054 | O12: =[2]datos!AS254 -> 82.774176 | P12: =[2]datos!AV254 -> 94.748607 | Q12: =[2]datos!AY254 -> 82.724557 | R12: =[2]datos!BB254 -> 96.40866 | S12: =[2]datos!BE254 -> 105.59625 | T12: =[2]datos!BH254 -> 100.21102 | U12: =[2]datos!BK254 -> 82.562359 | V12: =[2]datos!BN254 -> 91.580623 | W12: =[2]datos!BQ254 -> 178.36365 | X12: =[2]datos!BT254 -> 100.26499 | Y12: =[2]datos!BW254 -> 81.589038 | Z12: =[2]datos!BZ254 -> 88.959455 | AA12: =[2]datos!CC254 -> 95.590503 | AB12: =[2]datos!CF254 -> 94.057841 | AC12: =[2]datos!CI254 -> 81.993731 | AD12: =[2]datos!CL254 -> 77.449964 | AE12: =[2]datos!CO254 -> 88.785906 | AF12: =[2]datos!CR254 -> 74.916762 | AG12: =[2]datos!CU254 -> 105.1517 | AH12: =[2]datos!CX254 -> 74.68588 | AI12: =[3]Datos!D254 -> 92.815734
A13: 41609 | B13: =[2]datos!C255 -> 92.644823 | C13: =[2]datos!F255 -> 136.43813 | D13: =[2]datos!I255 -> 142.80957 | E13: =[2]datos!L255 -> 104.30133 | F13: =[2]datos!O255 -> 210.29472 | G13: =[2]datos!R255 -> 82.81654 | H13: =[2]datos!U255 -> 82.81654 | I13: =[2]datos!AA255 -> 101.63703 | J13: =[2]datos!AD255 -> 93.016686 | K13: =[2]datos!AG255 -> 166.15935 | L13: =[2]datos!AJ255 -> 76.16004 | M13: =[2]datos!AM255 -> 82.365316 | N13: =[2]datos!AP255 -> 93.565865 | O13: =[2]datos!AS255 -> 76.041697 | P13: =[2]datos!AV255 -> 83.442185 | Q13: =[2]datos!AY255 -> 77.019984 | R13: =[2]datos!BB255 -> 92.492256 | S13: =[2]datos!BE255 -> 85.492075 | T13: =[2]datos!BH255 -> 76.331119 | U13: =[2]datos!BK255 -> 78.882094 | V13: =[2]datos!BN255 -> 102.77924 | W13: =[2]datos!BQ255 -> 206.55821 | X13: =[2]datos!BT255 -> 96.192623 | Y13: =[2]datos!BW255 -> 71.516191 | Z13: =[2]datos!BZ255 -> 86.104774 | AA13: =[2]datos!CC255 -> 88.244609 | AB13: =[2]datos!CF255 -> 85.60968 | AC13: =[2]datos!CI255 -> 77.879462 | AD13: =[2]datos!CL255 -> 69.74838 | AE13: =[2]datos!CO255 -> 81.045838 | AF13: =[2]datos!CR255 -> 57.509762 | AG13: =[2]datos!CU255 -> 107.33969 | AH13: =[2]datos!CX255 -> 69.290475 | AI13: =[3]Datos!D255 -> 90.188301
... A169: 46357 | B169: =[2]datos!C411 -> 0 | C169: =[2]datos!F411 -> 0 | D169: =[2]datos!I411 -> 0 | E169: =[2]datos!L411 -> 0 | F169: =[2]datos!O411 -> 0 | G169: =[2]datos!R411 -> 0 | H169: =[2]datos!U411 -> 0 | I169: =[2]datos!AA411 -> 0 | J169: =[2]datos!AD411 -> 0 | K169: =[2]datos!AG411 -> 0 | L169: =[2]datos!AJ411 -> 0 | M169: =[2]datos!AM411 -> 0 | N169: =[2]datos!AP411 -> 0 | O169: =[2]datos!AS411 -> 0 | P169: =[2]datos!AV411 -> 0 | Q169: =[2]datos!AY411 -> 0 | R169: =[2]datos!BB411 -> 0 | S169: =[2]datos!BE411 -> 0 | T169: =[2]datos!BH411 -> 0 | U169: =[2]datos!BK411 -> 0 | V169: =[2]datos!BN411 -> 0 | W169: =[2]datos!BQ411 -> 0 | X169: =[2]datos!BT411 -> 0 | Y169: =[2]datos!BW411 -> 0 | Z169: =[2]datos!BZ411 -> 0 | AA169: =[2]datos!CC411 -> 0 | AB169: =[2]datos!CF411 -> 0 | AC169: =[2]datos!CI411 -> 0 | AD169: =[2]datos!CL411 -> 0 | AE169: =[2]datos!CO411 -> 0 | AF169: =[2]datos!CR411 -> 0 | AG169: =[2]datos!CU411 -> 0 | AH169: =[2]datos!CX411 -> 0 | AI169: =[3]Datos!D411 -> 0

Sheet DatosDesest
B1: ACTIVIDAD INDUSTRIAL | C1: Industria Minera | D1: Extracción de petróleo y gas | E1: Minería de minerales metálicos y no metálicos excepto petróleo y gas, y servicios relacionados | F1: Servicios relacionados con la minería | G1: Electricidad, agua y suministro de gas por ductos al consumidor fina | H1: Generación, transmisión y suministro de energía eléctrica | I1: Construcción | J1: Edificación | K1: Construcción de obras de ingeniería civil u obra pesada | L1: Trabajos especializados para la construcción | M1: Total industrias manufactureras | N1: Industria alimentaria | O1: Industria de las bebidas y del tabaco | P1: Fabricación de insumos textiles | Q1: Confección de productos textiles, excepto prendas de vestir | R1: Fabricación de prendas de vestir | S1: Fabricación de productos de cuero, piel y materiales sucedáneos, excepto prendas de vestir | T1: Industria de la madera | U1: Industria del papel | V1: Impresión e industrias conexas | W1: Fabricación de productos derivados del petróleo y del carbón | X1: Industria química | Y1: Industria del plástico y del hule | Z1: Fabricación de productos a base de minerales no metálicos | AA1: Industrias metálicas básicas | AB1: Fabricación de productos metálicos | AC1: Fabricación de maquinaria y equipo | AD1: Fabricación de equipo de computación, comunicación, medición y otros equipos, componentes y accesorios electrónicos | AE1: Fabricación de equipo de generación eléctrica y aparatos y accesorios eléctricos | AF1: Fabricación de equipo de transporte | AG1: Fabricación de muebles y productos relacionados | AH1: Otras industrias manufactureras | AI1: Manufacturas sin equipo de transporte
A2: 41275 | B2: =[2]datos!D244 -> 94.432567 | C2: =[2]datos!G244 -> 130.99027 | D2: =[2]datos!J244 -> 142.83464 | E2: =[2]datos!M244 -> 102.03058 | F2: =[2]datos!P244 -> 135.85582 | G2: =[2]datos!S244 -> 88.440964 | H2: =[2]datos!V244 -> 88.440964 | I2: =[2]datos!AB244 -> 94.279489 | J2: =[2]datos!AE244 -> 89.85965 | K2: =[2]datos!AH244 -> 135.60601 | L2: =[2]datos!AK244 -> 71.567383 | M2: =[2]datos!AN244 -> 88.108842 | N2: =[2]datos!AQ244 -> 89.09645 | O2: =[2]datos!AT244 -> 83.939149 | P2: =[2]datos!AW244 -> 98.176342 | Q2: =[2]datos!AZ244 -> 87.374917 | R2: =[2]datos!BC244 -> 87.868862 | S2: =[2]datos!BF244 -> 104.86981 | T2: =[2]datos!BI244 -> 104.09625 | U2: =[2]datos!BL244 -> 80.321935 | V2: =[2]datos!BO244 -> 89.250782 | W2: =[2]datos!BR244 -> 195.07369 | X2: =[2]datos!BU244 -> 105.04278 | Y2: =[2]datos!BX244 -> 84.665881 | Z2: =[2]datos!CA244 -> 89.316258 | AA2: =[2]datos!CD244 -> 95.868915 | AB2: =[2]datos!CG244 -> 94.193507 | AC2: =[2]datos!CJ244 -> 93.407189 | AD2: =[2]datos!CM244 -> 70.953564 | AE2: =[2]datos!CP244 -> 102.7872 | AF2: =[2]datos!CS244 -> 69.133575 | AG2: =[2]datos!CV244 -> 93.409603 | AH2: =[2]datos!CY244 -> 75.915211 | AI2: =[3]Datos!E244 -> 93.990611
A3: 41306 | B3: =[2]datos!D245 -> 95.132841 | C3: =[2]datos!G245 -> 129.99533 | D3: =[2]datos!J245 -> 141.55508 | E3: =[2]datos!M245 -> 102.44027 | F3: =[2]datos!P245 -> 123.42153 | G3: =[2]datos!S245 -> 87.985011 | H3: =[2]datos!V245 -> 87.985011 | I3: =[2]datos!AB245 -> 95.826107 | J3: =[2]datos!AE245 -> 92.315613 | K3: =[2]datos!AH245 -> 135.65409 | L3: =[2]datos!AK245 -> 68.997941 | M3: =[2]datos!AN245 -> 88.810366 | N3: =[2]datos!AQ245 -> 89.684951 | O3: =[2]datos!AT245 -> 84.561677 | P3: =[2]datos!AW245 -> 97.140364 | Q3: =[2]datos!AZ245 -> 93.659364 | R3: =[2]datos!BC245 -> 91.013072 | S3: =[2]datos!BF245 -> 103.77978 | T3: =[2]datos!BI245 -> 101.34733 | U3: =[2]datos!BL245 -> 81.188771 | V3: =[2]datos!BO245 -> 90.364442 | W3: =[2]datos!BR245 -> 186.97667 | X3: =[2]datos!BU245 -> 103.32143 | Y3: =[2]datos!BX245 -> 83.573185 | Z3: =[2]datos!CA245 -> 89.139942 | AA3: =[2]datos!CD245 -> 97.342092 | AB3: =[2]datos!CG245 -> 96.652003 | AC3: =[2]datos!CJ245 -> 91.839246 | AD3: =[2]datos!CM245 -> 72.323384 | AE3: =[2]datos!CP245 -> 103.73502 | AF3: =[2]datos!CS245 -> 70.774153 | AG3: =[2]datos!CV245 -> 93.211777 | AH3: =[2]datos!CY245 -> 75.618528 | AI3: =[3]Datos!E245 -> 94.726885
A4: 41334 | B4: =[2]datos!D246 -> 94.17289 | C4: =[2]datos!G246 -> 128.75054 | D4: =[2]datos!J246 -> 140.32009 | E4: =[2]datos!M246 -> 101.65472 | F4: =[2]datos!P246 -> 126.76582 | G4: =[2]datos!S246 -> 86.147293 | H4: =[2]datos!V246 -> 86.147293 | I4: =[2]datos!AB246 -> 94.734788 | J4: =[2]datos!AE246 -> 89.936718 | K4: =[2]datos!AH246 -> 136.3613 | L4: =[2]datos!AK246 -> 74.046333 | M4: =[2]datos!AN246 -> 88.040113 | N4: =[2]datos!AQ246 -> 89.425953 | O4: =[2]datos!AT246 -> 82.2757 | P4: =[2]datos!AW246 -> 96.935758 | Q4: =[2]datos!AZ246 -> 89.837419 | R4: =[2]datos!BC246 -> 91.404287 | S4: =[2]datos!BF246 -> 101.57133 | T4: =[2]datos!BI246 -> 92.907206 | U4: =[2]datos!BL246 -> 81.805641 | V4: =[2]datos!BO246 -> 92.530619 | W4: =[2]datos!BR246 -> 190.28843 | X4: =[2]datos!BU246 -> 104.0496 | Y4: =[2]datos!BX246 -> 83.318708 | Z4: =[2]datos!CA246 -> 88.533077 | AA4: =[2]datos!CD246 -> 100.00947 | AB4: =[2]datos!CG246 -> 96.092855 | AC4: =[2]datos!CJ246 -> 89.124927 | AD4: =[2]datos!CM246 -> 72.379583 | AE4: =[2]datos!CP246 -> 98.85156 | AF4: =[2]datos!CS246 -> 70.91881 | AG4: =[2]datos!CV246 -> 92.387369 | AH4: =[2]datos!CY246 -> 74.175816 | AI4: =[3]Datos!E246 -> 93.328157
A5: 41365 | B5: =[2]datos!D247 -> 93.244901 | C5: =[2]datos!G247 -> 128.2791 | D5: =[2]datos!J247 -> 140.52773 | E5: =[2]datos!M247 -> 98.098643 | F5: =[2]datos!P247 -> 133.76461 | G5: =[2]datos!S247 -> 86.877234 | H5: =[2]datos!V247 -> 86.877234 | I5: =[2]datos!AB247 -> 89.359696 | J5: =[2]datos!AE247 -> 83.012706 | K5: =[2]datos!AH247 -> 138.8812 | L5: =[2]datos!AK247 -> 70.588302 | M5: =[2]datos!AN247 -> 87.974249 | N5: =[2]datos!AQ247 -> 88.624122 | O5: =[2]datos!AT247 -> 81.397498 | P5: =[2]datos!AW247 -> 96.020575 | Q5: =[2]datos!AZ247 -> 95.22333 | R5: =[2]datos!BC247 -> 91.840548 | S5: =[2]datos!BF247 -> 102.30406 | T5: =[2]datos!BI247 -> 96.147431 | U5: =[2]datos!BL247 -> 81.371004 | V5: =[2]datos!BO247 -> 89.020973 | W5: =[2]datos!BR247 -> 190.40957 | X5: =[2]datos!BU247 -> 102.15604 | Y5: =[2]datos!BX247 -> 83.474422 | Z5: =[2]datos!CA247 -> 86.880774 | AA5: =[2]datos!CD247 -> 100.32825 | AB5: =[2]datos!CG247 -> 95.230905 | AC5: =[2]datos!CJ247 -> 94.194058 | AD5: =[2]datos!CM247 -> 73.417735 | AE5: =[2]datos!CP247 -> 96.593167 | AF5: =[2]datos!CS247 -> 70.010524 | AG5: =[2]datos!CV247 -> 91.232094 | AH5: =[2]datos!CY247 -> 73.394739 | AI5: =[3]Datos!E247 -> 93.755991
A6: 41395 | B6: =[2]datos!D248 -> 94.808658 | C6: =[2]datos!G248 -> 127.83353 | D6: =[2]datos!J248 -> 140.21487 | E6: =[2]datos!M248 -> 99.171335 | F6: =[2]datos!P248 -> 125.62589 | G6: =[2]datos!S248 -> 88.692881 | H6: =[2]datos!V248 -> 88.692881 | I6: =[2]datos!AB248 -> 95.285614 | J6: =[2]datos!AE248 -> 90.660671 | K6: =[2]datos!AH248 -> 140.10135 | L6: =[2]datos!AK248 -> 70.142117 | M6: =[2]datos!AN248 -> 88.945476 | N6: =[2]datos!AQ248 -> 89.388808 | O6: =[2]datos!AT248 -> 80.64495 | P6: =[2]datos!AW248 -> 93.504621 | Q6: =[2]datos!AZ248 -> 93.583958 | R6: =[2]datos!BC248 -> 92.316496 | S6: =[2]datos!BF248 -> 102.83282 | T6: =[2]datos!BI248 -> 92.602894 | U6: =[2]datos!BL248 -> 79.353268 | V6: =[2]datos!BO248 -> 90.492908 | W6: =[2]datos!BR248 -> 204.68017 | X6: =[2]datos!BU248 -> 103.48832 | Y6: =[2]datos!BX248 -> 83.385143 | Z6: =[2]datos!CA248 -> 87.763491 | AA6: =[2]datos!CD248 -> 94.838686 | AB6: =[2]datos!CG248 -> 96.180081 | AC6: =[2]datos!CJ248 -> 90.742695 | AD6: =[2]datos!CM248 -> 79.972088 | AE6: =[2]datos!CP248 -> 98.039022 | AF6: =[2]datos!CS248 -> 71.002736 | AG6: =[2]datos!CV248 -> 97.251879 | AH6: =[2]datos!CY248 -> 74.967457 | AI6: =[3]Datos!E248 -> 94.871493
A7: 41426 | B7: =[2]datos!D249 -> 93.830366 | C7: =[2]datos!G249 -> 127.36276 | D7: =[2]datos!J249 -> 140.73839 | E7: =[2]datos!M249 -> 96.735838 | F7: =[2]datos!P249 -> 125.61021 | G7: =[2]datos!S249 -> 87.921468 | H7: =[2]datos!V249 -> 87.921468 | I7: =[2]datos!AB249 -> 91.024999 | J7: =[2]datos!AE249 -> 84.732038 | K7: =[2]datos!AH249 -> 139.23052 | L7: =[2]datos!AK249 -> 70.951015 | M7: =[2]datos!AN249 -> 88.629392 | N7: =[2]datos!AQ249 -> 89.178151 | O7: =[2]datos!AT249 -> 80.266468 | P7: =[2]datos!AW249 -> 94.791511 | Q7: =[2]datos!AZ249 -> 88.749452 | R7: =[2]datos!BC249 -> 93.11169 | S7: =[2]datos!BF249 -> 103.64398 | T7: =[2]datos!BI249 -> 93.763304 | U7: =[2]datos!BL249 -> 79.872613 | V7: =[2]datos!BO249 -> 91.804522 | W7: =[2]datos!BR249 -> 202.12541 | X7: =[2]datos!BU249 -> 103.50403 | Y7: =[2]datos!BX249 -> 83.534008 | Z7: =[2]datos!CA249 -> 87.640172 | AA7: =[2]datos!CD249 -> 93.47986 | AB7: =[2]datos!CG249 -> 96.482563 | AC7: =[2]datos!CJ249 -> 87.921189 | AD7: =[2]datos!CM249 -> 76.128565 | AE7: =[2]datos!CP249 -> 94.982742 | AF7: =[2]datos!CS249 -> 72.14234 | AG7: =[2]datos!CV249 -> 95.369156 | AH7: =[2]datos!CY249 -> 75.428063 | AI7: =[3]Datos!E249 -> 93.930133
A8: 41456 | B8: =[2]datos!D250 -> 94.017831 | C8: =[2]datos!G250 -> 127.66146 | D8: =[2]datos!J250 -> 139.98234 | E8: =[2]datos!M250 -> 96.851265 | F8: =[2]datos!P250 -> 138.60706 | G8: =[2]datos!S250 -> 88.625263 | H8: =[2]datos!V250 -> 88.625263 | I8: =[2]datos!AB250 -> 91.73643 | J8: =[2]datos!AE250 -> 83.903287 | K8: =[2]datos!AH250 -> 145.7808 | L8: =[2]datos!AK250 -> 72.16343 | M8: =[2]datos!AN250 -> 88.750293 | N8: =[2]datos!AQ250 -> 89.19168 | O8: =[2]datos!AT250 -> 81.193174 | P8: =[2]datos!AW250 -> 92.221014 | Q8: =[2]datos!AZ250 -> 92.072617 | R8: =[2]datos!BC250 -> 96.379114 | S8: =[2]datos!BF250 -> 102.72854 | T8: =[2]datos!BI250 -> 97.683463 | U8: =[2]datos!BL250 -> 80.785769 | V8: =[2]datos!BO250 -> 86.1534 | W8: =[2]datos!BR250 -> 192.39256 | X8: =[2]datos!BU250 -> 105.06916 | Y8: =[2]datos!BX250 -> 83.516289 | Z8: =[2]datos!CA250 -> 87.747833 | AA8: =[2]datos!CD250 -> 97.93115 | AB8: =[2]datos!CG250 -> 94.871312 | AC8: =[2]datos!CJ250 -> 88.054482 | AD8: =[2]datos!CM250 -> 74.771636 | AE8: =[2]datos!CP250 -> 94.514857 | AF8: =[2]datos!CS250 -> 73.284322 | AG8: =[2]datos!CV250 -> 93.550386 | AH8: =[2]datos!CY250 -> 74.116413 | AI8: =[3]Datos!E250 -> 93.714517
A9: 41487 | B9: =[2]datos!D251 -> 94.899336 | C9: =[2]datos!G251 -> 127.81061 | D9: =[2]datos!J251 -> 140.17692 | E9: =[2]datos!M251 -> 96.625837 | F9: =[2]datos!P251 -> 139.37159 | G9: =[2]datos!S251 -> 88.685702 | H9: =[2]datos!V251 -> 88.685702 | I9: =[2]datos!AB251 -> 93.167978 | J9: =[2]datos!AE251 -> 87.41241 | K9: =[2]datos!AH251 -> 138.419 | L9: =[2]datos!AK251 -> 73.546627 | M9: =[2]datos!AN251 -> 89.642139 | N9: =[2]datos!AQ251 -> 90.382017 | O9: =[2]datos!AT251 -> 83.668046 | P9: =[2]datos!AW251 -> 91.867043 | Q9: =[2]datos!AZ251 -> 89.827874 | R9: =[2]datos!BC251 -> 95.682309 | S9: =[2]datos!BF251 -> 102.07373 | T9: =[2]datos!BI251 -> 100.39596 | U9: =[2]datos!BL251 -> 82.118269 | V9: =[2]datos!BO251 -> 82.249437 | W9: =[2]datos!BR251 -> 198.56541 | X9: =[2]datos!BU251 -> 106.1152 | Y9: =[2]datos!BX251 -> 83.117773 | Z9: =[2]datos!CA251 -> 87.824043 | AA9: =[2]datos!CD251 -> 98.197787 | AB9: =[2]datos!CG251 -> 96.270883 | AC9: =[2]datos!CJ251 -> 90.176307 | AD9: =[2]datos!CM251 -> 73.874627 | AE9: =[2]datos!CP251 -> 97.095016 | AF9: =[2]datos!CS251 -> 73.424346 | AG9: =[2]datos!CV251 -> 90.386294 | AH9: =[2]datos!CY251 -> 73.570026 | AI9: =[3]Datos!E251 -> 94.860446
A10: 41518 | B10: =[2]datos!D252 -> 94.026872 | C10: =[2]datos!G252 -> 127.61084 | D10: =[2]datos!J252 -> 141.16571 | E10: =[2]datos!M252 -> 93.892116 | F10: =[2]datos!P252 -> 137.17767 | G10: =[2]datos!S252 -> 87.980861 | H10: =[2]datos!V252 -> 87.980861 | I10: =[2]datos!AB252 -> 92.630429 | J10: =[2]datos!AE252 -> 87.576385 | K10: =[2]datos!AH252 -> 136.62876 | L10: =[2]datos!AK252 -> 71.165794 | M10: =[2]datos!AN252 -> 88.259204 | N10: =[2]datos!AQ252 -> 89.728956 | O10: =[2]datos!AT252 -> 80.018671 | P10: =[2]datos!AW252 -> 93.117938 | Q10: =[2]datos!AZ252 -> 88.863451 | R10: =[2]datos!BC252 -> 94.010932 | S10: =[2]datos!BF252 -> 102.59985 | T10: =[2]datos!BI252 -> 96.752941 | U10: =[2]datos!BL252 -> 81.611021 | V10: =[2]datos!BO252 -> 89.388374 | W10: =[2]datos!BR252 -> 190.56918 | X10: =[2]datos!BU252 -> 104.07211 | Y10: =[2]datos!BX252 -> 82.550363 | Z10: =[2]datos!CA252 -> 85.512645 | AA10: =[2]datos!CD252 -> 97.732569 | AB10: =[2]datos!CG252 -> 92.394774 | AC10: =[2]datos!CJ252 -> 88.412237 | AD10: =[2]datos!CM252 -> 76.622721 | AE10: =[2]datos!CP252 -> 92.410393 | AF10: =[2]datos!CS252 -> 73.801614 | AG10: =[2]datos!CV252 -> 95.306811 | AH10: =[2]datos!CY252 -> 72.834682 | AI10: =[3]Datos!E252 -> 92.559395
A11: 41548 | B11: =[2]datos!D253 -> 94.999593 | C11: =[2]datos!G253 -> 129.03328 | D11: =[2]datos!J253 -> 141.46601 | E11: =[2]datos!M253 -> 95.866549 | F11: =[2]datos!P253 -> 144.40133 | G11: =[2]datos!S253 -> 88.273579 | H11: =[2]datos!V253 -> 88.273579 | I11: =[2]datos!AB253 -> 93.927255 | J11: =[2]datos!AE253 -> 88.105343 | K11: =[2]datos!AH253 -> 139.51946 | L11: =[2]datos!AK253 -> 73.636332 | M11: =[2]datos!AN253 -> 89.39219 | N11: =[2]datos!AQ253 -> 90.261112 | O11: =[2]datos!AT253 -> 82.458693 | P11: =[2]datos!AW253 -> 92.996279 | Q11: =[2]datos!AZ253 -> 86.538249 | R11: =[2]datos!BC253 -> 96.230769 | S11: =[2]datos!BF253 -> 104.48353 | T11: =[2]datos!BI253 -> 105.24324 | U11: =[2]datos!BL253 -> 81.444617 | V11: =[2]datos!BO253 -> 83.953914 | W11: =[2]datos!BR253 -> 197.83602 | X11: =[2]datos!BU253 -> 105.38042 | Y11: =[2]datos!BX253 -> 81.863949 | Z11: =[2]datos!CA253 -> 87.462029 | AA11: =[2]datos!CD253 -> 99.655044 | AB11: =[2]datos!CG253 -> 94.160395 | AC11: =[2]datos!CJ253 -> 88.321237 | AD11: =[2]datos!CM253 -> 77.135788 | AE11: =[2]datos!CP253 -> 87.524734 | AF11: =[2]datos!CS253 -> 73.654523 | AG11: =[2]datos!CV253 -> 99.173492 | AH11: =[2]datos!CY253 -> 76.807746 | AI11: =[3]Datos!E253 -> 94.146559
A12: 41579 | B12: =[2]datos!D254 -> 94.740834 | C12: =[2]datos!G254 -> 129.88085 | D12: =[2]datos!J254 -> 140.42677 | E12: =[2]datos!M254 -> 101.36753 | F12: =[2]datos!P254 -> 146.71578 | G12: =[2]datos!S254 -> 89.125601 | H12: =[2]datos!V254 -> 89.125601 | I12: =[2]datos!AB254 -> 93.437538 | J12: =[2]datos!AE254 -> 86.692623 | K12: =[2]datos!AH254 -> 140.81959 | L12: =[2]datos!AK254 -> 76.250724 | M12: =[2]datos!AN254 -> 88.920771 | N12: =[2]datos!AQ254 -> 90.594092 | O12: =[2]datos!AT254 -> 82.407608 | P12: =[2]datos!AW254 -> 92.184384 | Q12: =[2]datos!AZ254 -> 84.82409 | R12: =[2]datos!BC254 -> 92.578091 | S12: =[2]datos!BF254 -> 103.42858 | T12: =[2]datos!BI254 -> 103.25235 | U12: =[2]datos!BL254 -> 82.715657 | V12: =[2]datos!BO254 -> 85.462408 | W12: =[2]datos!BR254 -> 191.55104 | X12: =[2]datos!BU254 -> 102.33305 | Y12: =[2]datos!BX254 -> 83.106013 | Z12: =[2]datos!CA254 -> 88.812692 | AA12: =[2]datos!CD254 -> 98.281104 | AB12: =[2]datos!CG254 -> 94.013822 | AC12: =[2]datos!CJ254 -> 85.834424 | AD12: =[2]datos!CM254 -> 74.985322 | AE12: =[2]datos!CP254 -> 93.072041 | AF12: =[2]datos!CS254 -> 73.712343 | AG12: =[2]datos!CV254 -> 96.970695 | AH12: =[2]datos!CY254 -> 77.871712 | AI12: =[3]Datos!E254 -> 93.707127
A13: 41609 | B13: =[2]datos!D255 -> 95.02048 | C13: =[2]datos!G255 -> 130.34572 | D13: =[2]datos!J255 -> 140.21171 | E13: =[2]datos!M255 -> 104.48613 | F13: =[2]datos!P255 -> 146.89394 | G13: =[2]datos!S255 -> 88.57254 | H13: =[2]datos!V255 -> 88.57254 | I13: =[2]datos!AB255 -> 94.792728 | J13: =[2]datos!AE255 -> 88.492086 | K13: =[2]datos!AH255 -> 142.41846 | L13: =[2]datos!AK255 -> 74.48091 | M13: =[2]datos!AN255 -> 88.551377 | N13: =[2]datos!AQ255 -> 90.683635 | O13: =[2]datos!AT255 -> 80.293931 | P13: =[2]datos!AW255 -> 95.700973 | Q13: =[2]datos!AZ255 -> 86.114301 | R13: =[2]datos!BC255 -> 98.332118 | S13: =[2]datos!BF255 -> 100.49112 | T13: =[2]datos!BI255 -> 92.18733 | U13: =[2]datos!BL255 -> 82.477378 | V13: =[2]datos!BO255 -> 87.327987 | W13: =[2]datos!BR255 -> 205.72208 | X13: =[2]datos!BU255 -> 103.02554 | Y13: =[2]datos!BX255 -> 82.665114 | Z13: =[2]datos!CA255 -> 88.604632 | AA13: =[2]datos!CD255 -> 95.412569 | AB13: =[2]datos!CG255 -> 95.077134 | AC13: =[2]datos!CJ255 -> 86.736677 | AD13: =[2]datos!CM255 -> 75.804038 | AE13: =[2]datos!CP255 -> 91.075651 | AF13: =[2]datos!CS255 -> 71.189072 | AG13: =[2]datos!CV255 -> 98.746487 | AH13: =[2]datos!CY255 -> 76.401319 | AI13: =[3]Datos!E255 -> 93.933586
... A169: 46357 | B169: =[2]datos!D411 -> 0 | C169: =[2]datos!G411 -> 0 | D169: =[2]datos!J411 -> 0 | E169: =[2]datos!M411 -> 0 | F169: =[2]datos!P411 -> 0 | G169: =[2]datos!S411 -> 0 | H169: =[2]datos!V411 -> 0 | I169: =[2]datos!AB411 -> 0 | J169: =[2]datos!AE411 -> 0 | K169: =[2]datos!AH411 -> 0 | L169: =[2]datos!AK411 -> 0 | M169: =[2]datos!AN411 -> 0 | N169: =[2]datos!AQ411 -> 0 | O169: =[2]datos!AT411 -> 0 | P169: =[2]datos!AW411 -> 0 | Q169: =[2]datos!AZ411 -> 0 | R169: =[2]datos!BC411 -> 0 | S169: =[2]datos!BF411 -> 0 | T169: =[2]datos!BI411 -> 0 | U169: =[2]datos!BL411 -> 0 | V169: =[2]datos!BO411 -> 0 | W169: =[2]datos!BR411 -> 0 | X169: =[2]datos!BU411 -> 0 | Y169: =[2]datos!BX411 -> 0 | Z169: =[2]datos!CA411 -> 0 | AA169: =[2]datos!CD411 -> 0 | AB169: =[2]datos!CG411 -> 0 | AC169: =[2]datos!CJ411 -> 0 | AD169: =[2]datos!CM411 -> 0 | AE169: =[2]datos!CP411 -> 0 | AF169: =[2]datos!CS411 -> 0 | AG169: =[2]datos!CV411 -> 0 | AH169: =[2]datos!CY411 -> 0 | AI169: =[3]Datos!E411 -> 0

Sheet DContriORI
E1: 2 | F1: =+E1+1 -> 3 | G1: =+F1+1 -> 4 | H1: =+G1+1 -> 5 | I1: =+H1+1 -> 6 | J1: =+I1+1 -> 7 | K1: =+J1+1 -> 8 | L1: =+K1+1 -> 9 | M1: =+L1+1 -> 10 | ... FP1: =+FO1+1 -> 169
B2: Originales
B5: Índices IMAI | E5: 41275 | F5: =+EDATE(E5,1) -> 41306 | G5: =+EDATE(F5,1) -> 41334 | H5: =+EDATE(G5,1) -> 41365 | I5: =+EDATE(H5,1) -> 41395 | J5: =+EDATE(I5,1) -> 41426 | K5: =+EDATE(J5,1) -> 41456 | L5: =+EDATE(K5,1) -> 41487 | M5: =+EDATE(L5,1) -> 41518 | ... FP5: =+EDATE(FO5,1) -> 46357
B6: SERIES ORIGINALES | C6: PIB 2018
A7: B | B7: ACTIVIDAD INDUSTRIAL | C7: =Ponderadores!B5 -> 7747139.7 | E7: =+INDIRECT("DatosOri!"&$A7&E$1) -> 91.795723 | F7: =+INDIRECT("DatosOri!"&$A7&F$1) -> 90.795957 | G7: =+INDIRECT("DatosOri!"&$A7&G$1) -> 92.46148 | H7: =+INDIRECT("DatosOri!"&$A7&H$1) -> 95.217513 | I7: =+INDIRECT("DatosOri!"&$A7&I$1) -> 96.751212 | J7: =+INDIRECT("DatosOri!"&$A7&J$1) -> 93.300123 | K7: =+INDIRECT("DatosOri!"&$A7&K$1) -> 96.415834 | L7: =+INDIRECT("DatosOri!"&$A7&L$1) -> 96.179258 | ... FP7: =+INDIRECT("DatosOri!"&$A7&FP$1) -> 0
A8: C | B8: Industria Minera | C8: =Ponderadores!B6 -> 948326.58 | E8: =+INDIRECT("DatosOri!"&$A8&E$1) -> 131.03121 | F8: =+INDIRECT("DatosOri!"&$A8&F$1) -> 121.39022 | G8: =+INDIRECT("DatosOri!"&$A8&G$1) -> 131.90808 | H8: =+INDIRECT("DatosOri!"&$A8&H$1) -> 128.03237 | I8: =+INDIRECT("DatosOri!"&$A8&I$1) -> 129.29213 | J8: =+INDIRECT("DatosOri!"&$A8&J$1) -> 126.35874 | K8: =+INDIRECT("DatosOri!"&$A8&K$1) -> 131.84997 | L8: =+INDIRECT("DatosOri!"&$A8&L$1) -> 127.50701 | ... FP8: =+INDIRECT("DatosOri!"&$A8&FP$1) -> 0
A9: D | B9: Extracción de petróleo y gas | C9: =Ponderadores!B7 -> 621540.6 | E9: =+INDIRECT("DatosOri!"&$A9&E$1) -> 146.19492 | F9: =+INDIRECT("DatosOri!"&$A9&F$1) -> 131.35293 | G9: =+INDIRECT("DatosOri!"&$A9&G$1) -> 143.33694 | H9: =+INDIRECT("DatosOri!"&$A9&H$1) -> 138.38781 | I9: =+INDIRECT("DatosOri!"&$A9&I$1) -> 142.7035 | J9: =+INDIRECT("DatosOri!"&$A9&J$1) -> 138.61696 | K9: =+INDIRECT("DatosOri!"&$A9&K$1) -> 141.31628 | L9: =+INDIRECT("DatosOri!"&$A9&L$1) -> 142.82885 | ... FP9: =+INDIRECT("DatosOri!"&$A9&FP$1) -> 0
A10: E | B10: Minería de minerales metálicos y no metálicos excepto petróleo y gas, y servicios relacionados | C10: =Ponderadores!B8 -> 265067.55 | E10: =+INDIRECT("DatosOri!"&$A10&E$1) -> 102.43443 | F10: =+INDIRECT("DatosOri!"&$A10&F$1) -> 98.436452 | G10: =+INDIRECT("DatosOri!"&$A10&G$1) -> 102.58752 | H10: =+INDIRECT("DatosOri!"&$A10&H$1) -> 101.74208 | I10: =+INDIRECT("DatosOri!"&$A10&I$1) -> 103.31478 | J10: =+INDIRECT("DatosOri!"&$A10&J$1) -> 97.461431 | K10: =+INDIRECT("DatosOri!"&$A10&K$1) -> 95.486071 | L10: =+INDIRECT("DatosOri!"&$A10&L$1) -> 95.16551 | ... FP10: =+INDIRECT("DatosOri!"&$A10&FP$1) -> 0
A11: F | B11: Servicios relacionados con la minería | C11: =Ponderadores!B9 -> 61718.433 | E11: =+INDIRECT("DatosOri!"&$A11&E$1) -> 101.14098 | F11: =+INDIRECT("DatosOri!"&$A11&F$1) -> 119.64152 | G11: =+INDIRECT("DatosOri!"&$A11&G$1) -> 142.73832 | H11: =+INDIRECT("DatosOri!"&$A11&H$1) -> 136.65822 | I11: =+INDIRECT("DatosOri!"&$A11&I$1) -> 105.79898 | J11: =+INDIRECT("DatosOri!"&$A11&J$1) -> 127.01906 | K11: =+INDIRECT("DatosOri!"&$A11&K$1) -> 192.69389 | L11: =+INDIRECT("DatosOri!"&$A11&L$1) -> 112.10708 | ... FP11: =+INDIRECT("DatosOri!"&$A11&FP$1) -> 0
A12: G | B12: Electricidad, agua y suministro de gas por ductos al consumidor fina | C12: =Ponderadores!B10 -> 456907.22 | E12: =+INDIRECT("DatosOri!"&$A12&E$1) -> 83.150627 | F12: =+INDIRECT("DatosOri!"&$A12&F$1) -> 80.252433 | G12: =+INDIRECT("DatosOri!"&$A12&G$1) -> 82.735247 | H12: =+INDIRECT("DatosOri!"&$A12&H$1) -> 85.399436 | I12: =+INDIRECT("DatosOri!"&$A12&I$1) -> 90.687446 | J12: =+INDIRECT("DatosOri!"&$A12&J$1) -> 91.924812 | K12: =+INDIRECT("DatosOri!"&$A12&K$1) -> 94.359289 | L12: =+INDIRECT("DatosOri!"&$A12&L$1) -> 95.432006 | ... FP12: =+INDIRECT("DatosOri!"&$A12&FP$1) -> 0
A13: H | B13: Generación, transmisión y suministro de energía eléctrica | C13: =Ponderadores!B11 -> 456907.22 | E13: =+INDIRECT("DatosOri!"&$A13&E$1) -> 83.150627 | F13: =+INDIRECT("DatosOri!"&$A13&F$1) -> 80.252433 | G13: =+INDIRECT("DatosOri!"&$A13&G$1) -> 82.735247 | H13: =+INDIRECT("DatosOri!"&$A13&H$1) -> 85.399436 | I13: =+INDIRECT("DatosOri!"&$A13&I$1) -> 90.687446 | J13: =+INDIRECT("DatosOri!"&$A13&J$1) -> 91.924812 | K13: =+INDIRECT("DatosOri!"&$A13&K$1) -> 94.359289 | L13: =+INDIRECT("DatosOri!"&$A13&L$1) -> 95.432006 | ... FP13: =+INDIRECT("DatosOri!"&$A13&FP$1) -> 0
A14: I | B14: Construcción | C14: =Ponderadores!B13 -> 1460789.5 | E14: =+INDIRECT("DatosOri!"&$A14&E$1) -> 86.606116 | F14: =+INDIRECT("DatosOri!"&$A14&F$1) -> 94.162325 | G14: =+INDIRECT("DatosOri!"&$A14&G$1) -> 87.044218 | H14: =+INDIRECT("DatosOri!"&$A14&H$1) -> 91.490406 | I14: =+INDIRECT("DatosOri!"&$A14&I$1) -> 96.070223 | J14: =+INDIRECT("DatosOri!"&$A14&J$1) -> 86.543008 | K14: =+INDIRECT("DatosOri!"&$A14&K$1) -> 93.846601 | L14: =+INDIRECT("DatosOri!"&$A14&L$1) -> 92.797342 | ... FP14: =+INDIRECT("DatosOri!"&$A14&FP$1) -> 0
A15: J | B15: Edificación | C15: =Ponderadores!B14 -> 1064926.3 | E15: =+INDIRECT("DatosOri!"&$A15&E$1) -> 81.275283 | F15: =+INDIRECT("DatosOri!"&$A15&F$1) -> 93.879487 | G15: =+INDIRECT("DatosOri!"&$A15&G$1) -> 83.592658 | H15: =+INDIRECT("DatosOri!"&$A15&H$1) -> 88.610517 | I15: =+INDIRECT("DatosOri!"&$A15&I$1) -> 92.591263 | J15: =+INDIRECT("DatosOri!"&$A15&J$1) -> 79.169182 | K15: =+INDIRECT("DatosOri!"&$A15&K$1) -> 85.491504 | L15: =+INDIRECT("DatosOri!"&$A15&L$1) -> 87.745813 | ... FP15: =+INDIRECT("DatosOri!"&$A15&FP$1) -> 0
A16: K | B16: Construcción de obras de ingeniería civil u obra pesada | C16: =Ponderadores!B15 -> 214062.02 | E16: =+INDIRECT("DatosOri!"&$A16&E$1) -> 126.51361 | F16: =+INDIRECT("DatosOri!"&$A16&F$1) -> 118.42818 | G16: =+INDIRECT("DatosOri!"&$A16&G$1) -> 118.07519 | H16: =+INDIRECT("DatosOri!"&$A16&H$1) -> 123.81905 | I16: =+INDIRECT("DatosOri!"&$A16&I$1) -> 132.18548 | J16: =+INDIRECT("DatosOri!"&$A16&J$1) -> 137.02436 | K16: =+INDIRECT("DatosOri!"&$A16&K$1) -> 153.42713 | L16: =+INDIRECT("DatosOri!"&$A16&L$1) -> 135.02593 | ... FP16: =+INDIRECT("DatosOri!"&$A16&FP$1) -> 0
A17: L | B17: Trabajos especializados para la construcción | C17: =Ponderadores!B16 -> 181801.25 | E17: =+INDIRECT("DatosOri!"&$A17&E$1) -> 70.84311 | F17: =+INDIRECT("DatosOri!"&$A17&F$1) -> 67.247236 | G17: =+INDIRECT("DatosOri!"&$A17&G$1) -> 70.724775 | H17: =+INDIRECT("DatosOri!"&$A17&H$1) -> 70.294376 | I17: =+INDIRECT("DatosOri!"&$A17&I$1) -> 73.924785 | J17: =+INDIRECT("DatosOri!"&$A17&J$1) -> 70.296919 | K17: =+INDIRECT("DatosOri!"&$A17&K$1) -> 72.634616 | L17: =+INDIRECT("DatosOri!"&$A17&L$1) -> 72.665294 | ... FP17: =+INDIRECT("DatosOri!"&$A17&FP$1) -> 0
A18: M | B18: Total industrias manufactureras | C18: =Ponderadores!B17 -> 4881116.4 | E18: =+INDIRECT("DatosOri!"&$A18&E$1) -> 86.535219 | F18: =+INDIRECT("DatosOri!"&$A18&F$1) -> 84.831441 | G18: =+INDIRECT("DatosOri!"&$A18&G$1) -> 87.329295 | H18: =+INDIRECT("DatosOri!"&$A18&H$1) -> 90.876553 | I18: =+INDIRECT("DatosOri!"&$A18&I$1) -> 91.200421 | J18: =+INDIRECT("DatosOri!"&$A18&J$1) -> 89.028303 | K18: =+INDIRECT("DatosOri!"&$A18&K$1) -> 90.492933 | L18: =+INDIRECT("DatosOri!"&$A18&L$1) -> 91.174819 | ... FP18: =+INDIRECT("DatosOri!"&$A18&FP$1) -> 0
A19: N | B19: Industria alimentaria | C19: =Ponderadores!B18 -> 911713.77 | E19: =+INDIRECT("DatosOri!"&$A19&E$1) -> 92.595093 | F19: =+INDIRECT("DatosOri!"&$A19&F$1) -> 90.278462 | G19: =+INDIRECT("DatosOri!"&$A19&G$1) -> 92.45331 | H19: =+INDIRECT("DatosOri!"&$A19&H$1) -> 92.320233 | I19: =+INDIRECT("DatosOri!"&$A19&I$1) -> 90.369501 | J19: =+INDIRECT("DatosOri!"&$A19&J$1) -> 85.01728 | K19: =+INDIRECT("DatosOri!"&$A19&K$1) -> 87.174524 | L19: =+INDIRECT("DatosOri!"&$A19&L$1) -> 88.625028 | ... FP19: =+INDIRECT("DatosOri!"&$A19&FP$1) -> 0
A20: O | B20: Industria de las bebidas y del tabaco | C20: =Ponderadores!B19 -> 240174.37 | E20: =+INDIRECT("DatosOri!"&$A20&E$1) -> 74.599987 | F20: =+INDIRECT("DatosOri!"&$A20&F$1) -> 72.448995 | G20: =+INDIRECT("DatosOri!"&$A20&G$1) -> 80.047465 | H20: =+INDIRECT("DatosOri!"&$A20&H$1) -> 85.40994 | I20: =+INDIRECT("DatosOri!"&$A20&I$1) -> 87.788275 | J20: =+INDIRECT("DatosOri!"&$A20&J$1) -> 83.97204 | K20: =+INDIRECT("DatosOri!"&$A20&K$1) -> 86.911028 | L20: =+INDIRECT("DatosOri!"&$A20&L$1) -> 89.725693 | ... FP20: =+INDIRECT("DatosOri!"&$A20&FP$1) -> 0
A21: P | B21: Fabricación de insumos textiles | C21: =Ponderadores!B20 -> 32513.579 | E21: =+INDIRECT("DatosOri!"&$A21&E$1) -> 91.391605 | F21: =+INDIRECT("DatosOri!"&$A21&F$1) -> 94.141938 | G21: =+INDIRECT("DatosOri!"&$A21&G$1) -> 91.892847 | H21: =+INDIRECT("DatosOri!"&$A21&H$1) -> 96.82572 | I21: =+INDIRECT("DatosOri!"&$A21&I$1) -> 92.577166 | J21: =+INDIRECT("DatosOri!"&$A21&J$1) -> 95.424174 | K21: =+INDIRECT("DatosOri!"&$A21&K$1) -> 98.46817 | L21: =+INDIRECT("DatosOri!"&$A21&L$1) -> 99.364545 | ... FP21: =+INDIRECT("DatosOri!"&$A21&FP$1) -> 0
A22: Q | B22: Confección de productos textiles, excepto prendas de vestir | C22: =Ponderadores!B21 -> 17328.629 | E22: =+INDIRECT("DatosOri!"&$A22&E$1) -> 77.216511 | F22: =+INDIRECT("DatosOri!"&$A22&F$1) -> 84.400199 | G22: =+INDIRECT("DatosOri!"&$A22&G$1) -> 81.825591 | H22: =+INDIRECT("DatosOri!"&$A22&H$1) -> 98.224748 | I22: =+INDIRECT("DatosOri!"&$A22&I$1) -> 96.694065 | J22: =+INDIRECT("DatosOri!"&$A22&J$1) -> 91.553951 | K22: =+INDIRECT("DatosOri!"&$A22&K$1) -> 94.079693 | L22: =+INDIRECT("DatosOri!"&$A22&L$1) -> 98.576793 | ... FP22: =+INDIRECT("DatosOri!"&$A22&FP$1) -> 0
A23: R | B23: Fabricación de prendas de vestir | C23: =Ponderadores!B22 -> 71182.811 | E23: =+INDIRECT("DatosOri!"&$A23&E$1) -> 80.603364 | F23: =+INDIRECT("DatosOri!"&$A23&F$1) -> 86.179975 | G23: =+INDIRECT("DatosOri!"&$A23&G$1) -> 85.600122 | H23: =+INDIRECT("DatosOri!"&$A23&H$1) -> 91.608591 | I23: =+INDIRECT("DatosOri!"&$A23&I$1) -> 89.75507 | J23: =+INDIRECT("DatosOri!"&$A23&J$1) -> 91.480466 | K23: =+INDIRECT("DatosOri!"&$A23&K$1) -> 102.64 | L23: =+INDIRECT("DatosOri!"&$A23&L$1) -> 99.470153 | ... FP23: =+INDIRECT("DatosOri!"&$A23&FP$1) -> 0
A24: S | B24: Fabricación de productos de cuero, piel y materiales sucedáneos, excepto prendas de vestir | C24: =Ponderadores!B23 -> 31436.957 | E24: =+INDIRECT("DatosOri!"&$A24&E$1) -> 100.61752 | F24: =+INDIRECT("DatosOri!"&$A24&F$1) -> 99.554232 | G24: =+INDIRECT("DatosOri!"&$A24&G$1) -> 103.65714 | H24: =+INDIRECT("DatosOri!"&$A24&H$1) -> 102.35642 | I24: =+INDIRECT("DatosOri!"&$A24&I$1) -> 105.89182 | J24: =+INDIRECT("DatosOri!"&$A24&J$1) -> 103.94763 | K24: =+INDIRECT("DatosOri!"&$A24&K$1) -> 108.11858 | L24: =+INDIRECT("DatosOri!"&$A24&L$1) -> 103.91479 | ... FP24: =+INDIRECT("DatosOri!"&$A24&FP$1) -> 0
A25: T | B25: Industria de la madera | C25: =Ponderadores!B24 -> 38837.812 | E25: =+INDIRECT("DatosOri!"&$A25&E$1) -> 90.440143 | F25: =+INDIRECT("DatosOri!"&$A25&F$1) -> 93.577037 | G25: =+INDIRECT("DatosOri!"&$A25&G$1) -> 102.93573 | H25: =+INDIRECT("DatosOri!"&$A25&H$1) -> 104.87881 | I25: =+INDIRECT("DatosOri!"&$A25&I$1) -> 100.37526 | J25: =+INDIRECT("DatosOri!"&$A25&J$1) -> 110.48205 | K25: =+INDIRECT("DatosOri!"&$A25&K$1) -> 100.94666 | L25: =+INDIRECT("DatosOri!"&$A25&L$1) -> 105.61718 | ... FP25: =+INDIRECT("DatosOri!"&$A25&FP$1) -> 0
... A39: AH | B39: Otras industrias manufactureras | C39: =Ponderadores!B38 -> 132857.27 | E39: =+INDIRECT("DatosOri!"&$A39&E$1) -> 70.670338 | F39: =+INDIRECT("DatosOri!"&$A39&F$1) -> 69.498124 | G39: =+INDIRECT("DatosOri!"&$A39&G$1) -> 71.973344 | H39: =+INDIRECT("DatosOri!"&$A39&H$1) -> 76.025253 | I39: =+INDIRECT("DatosOri!"&$A39&I$1) -> 76.230568 | J39: =+INDIRECT("DatosOri!"&$A39&J$1) -> 82.326947 | K39: =+INDIRECT("DatosOri!"&$A39&K$1) -> 74.986197 | L39: =+INDIRECT("DatosOri!"&$A39&L$1) -> 75.328311 | ... FP39: =+INDIRECT("DatosOri!"&$A39&FP$1) -> 0
A40: AI | B40: Manufacturas sin equipo de transporte | C40: =Ponderadores!C17 -> 3712615.6 | E40: =+INDIRECT("DatosOri!"&$A40&E$1) -> 92.713662 | F40: =+INDIRECT("DatosOri!"&$A40&F$1) -> 90.071086 | G40: =+INDIRECT("DatosOri!"&$A40&G$1) -> 93.088498 | H40: =+INDIRECT("DatosOri!"&$A40&H$1) -> 96.498355 | I40: =+INDIRECT("DatosOri!"&$A40&I$1) -> 97.083827 | J40: =+INDIRECT("DatosOri!"&$A40&J$1) -> 93.574874 | K40: =+INDIRECT("DatosOri!"&$A40&K$1) -> 95.854674 | L40: =+INDIRECT("DatosOri!"&$A40&L$1) -> 96.100423 | ... FP40: =+INDIRECT("DatosOri!"&$A40&FP$1) -> 0
B42: PIB Actividad Industrial | E42: =+E5 -> 41275 | F42: =+F5 -> 41306 | G42: =+G5 -> 41334 | H42: =+H5 -> 41365 | I42: =+I5 -> 41395 | J42: =+J5 -> 41426 | K42: =+K5 -> 41456 | L42: =+L5 -> 41487 | ... FP42: =+FP5 -> 46357
B43: SERIES ORIGINALES | C43: =+C6 -> PIB 2018
B44: ACTIVIDAD INDUSTRIAL | C44: =C49 -> 7747139.7 | E44: =+E49 -> 7111542.9 | F44: =+F49 -> 7034089.7 | G44: =+G49 -> 7163120 | H44: =+H49 -> 7376633.8 | I44: =+I49 -> 7495451.5 | J44: =+J49 -> 7228090.9 | K44: =+K49 -> 7469469.4 | L44: =+L49 -> 7451141.5 | ... FP44: =+FP49 -> 0
B45: Industria Minera | C45: =C50 -> 948326.58 | E45: =+E50 -> 1242603.8 | F45: =+F50 -> 1151175.8 | G45: =+G50 -> 1250919.4 | H45: =+H50 -> 1214165 | I45: =+I50 -> 1226111.6 | J45: =+J50 -> 1198293.5 | K45: =+K50 -> 1250368.3 | L45: =+L50 -> 1209182.9 | ... FP45: =+FP50 -> 0
B46: Electricidad, agua y suministro de gas por ductos al consumidor fina | C46: =C54 -> 456907.22 | E46: =+E54 -> 379921.22 | F46: =+F54 -> 366679.16 | G46: =+G54 -> 378023.32 | H46: =+H54 -> 390196.19 | I46: =+I54 -> 414357.49 | J46: =+J54 -> 420011.11 | K46: =+K54 -> 431134.41 | L46: =+L54 -> 436035.73 | ... FP46: =+FP54 -> 0
B47: Construcción | C47: =C56 -> 1460789.5 | E47: =+E56 -> 1265133.1 | F47: =+F56 -> 1375513.4 | G47: =+G56 -> 1271532.8 | H47: =+H56 -> 1336482.3 | I47: =+I56 -> 1403383.8 | J47: =+J56 -> 1264211.2 | K47: =+K56 -> 1370901.3 | L47: =+L56 -> 1355573.8 | ... FP47: =+FP56 -> 0
B48: Total industrias manufactureras | C48: =C60 -> 4881116.4 | E48: =+E60 -> 4223884.8 | F48: =+F60 -> 4140721.4 | G48: =+G60 -> 4262644.5 | H48: =+H60 -> 4435790.3 | I48: =+I60 -> 4451598.7 | J48: =+J60 -> 4345575.1 | K48: =+K60 -> 4417065.4 | L48: =+L60 -> 4450349 | ... FP48: =+FP60 -> 0
B49: ACTIVIDAD INDUSTRIAL | C49: =C50+C54+C56+C60 -> 7747139.7 | E49: =(E7/100)*$C7 -> 7111542.9 | F49: =(F7/100)*$C7 -> 7034089.7 | G49: =(G7/100)*$C7 -> 7163120 | H49: =(H7/100)*$C7 -> 7376633.8 | I49: =(I7/100)*$C7 -> 7495451.5 | J49: =(J7/100)*$C7 -> 7228090.9 | K49: =(K7/100)*$C7 -> 7469469.4 | L49: =(L7/100)*$C7 -> 7451141.5 | ... FP49: =(FP7/100)*$C7 -> 0
B50: Industria Minera | C50: =SUM(C51:C53) -> 948326.58 | E50: =(E8/100)*$C8 -> 1242603.8 | F50: =(F8/100)*$C8 -> 1151175.8 | G50: =(G8/100)*$C8 -> 1250919.4 | H50: =(H8/100)*$C8 -> 1214165 | I50: =(I8/100)*$C8 -> 1226111.6 | J50: =(J8/100)*$C8 -> 1198293.5 | K50: =(K8/100)*$C8 -> 1250368.3 | L50: =(L8/100)*$C8 -> 1209182.9 | ... FP50: =(FP8/100)*$C8 -> 0
