Workbook
Name Indicadores20251211131219: ORG!$A$1:$AI$410
Name Indicadores20251211133442: DES!$A$1:$AH$410
Name Indicadores20251211161923: TEND!$A$1:$AH$410

Sheet ORG
A1: National Institute of Statistics and Geography (INEGI)
A2: Economic Information Bank
A3: Consult Date: 11/02/2026 06:30:15
A4: Índice base 2018=100
C5: 1 | D5: 21 | E5: 211 | F5: 212 | G5: 213 | H5: 22 | I5: 221 | J5: 23 | K5: 236 | L5: 237 | M5: 238 | N5: 31 | O5: 311 | P5: 312 | Q5: 313 | R5: 314 | S5: 315 | T5: 316 | U5: 321 | V5: 322 | W5: 323 | X5: 324 | Y5: 325 | Z5: 326 | AA5: 327 | AB5: 331 | AC5: 332 | AD5: 333 | AE5: 334 | AF5: 335 | AG5: 336 | AH5: 337 | AI5: 339
A6: Period | B6: Geographic area | C6: Indicadores económicos de coyuntura > Actividad industrial, base 2018 > Series Originales > Índice de volumen físico > Total de la actividad industrial (Índice base 2018=100) Monthly /f1 | D6: Indicadores económicos de coyuntura > Actividad industrial, base 2018 > Series Originales > Índice de volumen físico > 21 Minería > Total minería (Índice base 2018=100) Monthly /f1 | E6: Indicadores económicos de coyuntura > Actividad industrial, base 2018 > Series Originales > Índice de volumen físico > 21 Minería > 211 Extracción de petróleo y gas (Índice base 2018=100) Monthly /f1 | F6: Indicadores económicos de coyuntura > Actividad industrial, base 2018 > Series Originales > Índice de volumen físico > 21 Minería > 212 Minería de minerales metálicos y no metálicos excepto petróleo y gas (Índice base 2018=100) Monthly /f1 | G6: Indicadores económicos de coyuntura > Actividad industrial, base 2018 > Series Originales > Índice de volumen físico > 21 Minería > 213 Servicios relacionados con la minería (Índice base 2018=100) Monthly /f1 | H6: Indicadores económicos de coyuntura > Actividad industrial, base 2018 > Series Originales > Índice de volumen físico > 22 Generación, transmisión y distribución de energía eléctrica, suministro de agua y de gas por ductos al consumidor final > Total generación, transmisión y distribución de energía eléctrica, suministro de agua y de gas por ductos al consumidor final (Índice base 2018=100) Monthly /f1 | I6: Indicadores económicos de coyuntura > Actividad industrial, base 2018 > Series Originales > Índice de volumen físico > 22 Generación, transmisión y distribución de energía eléctrica, suministro de agua y de gas por ductos al consumidor final > 221 Generación, transmisión, distribución y comercialización de energía eléctrica, suministro de agua y de gas natural por ductos al consumidor final (Índice base 2018=100) Monthly /f1 | J6: Indicadores económicos de coyuntura > Actividad industrial, base 2018 > Series Originales > Índice de volumen físico > 23 Construcción > Total construcción (Índice base 2018=100) Monthly /f1 | K6: Indicadores económicos de coyuntura > Actividad industrial, base 2018 > Series Originales > Índice de volumen físico > 23 Construcción > 236 Edificación (Índice base 2018=100) Monthly /f1 | L6: Indicadores económicos de coyuntura > Actividad industrial, base 2018 > Series Originales > Índice de volumen físico > 23 Construcción > 237 Construcción de obras de ingeniería civil (Índice base 2018=100) Monthly /f1 | M6: Indicadores económicos de coyuntura > Actividad industrial, base 2018 > Series Originales > Índice de volumen físico > 23 Construcción > 238 Trabajos especializados para la construcción (Índice base 2018=100) Monthly /f1 | N6: Indicadores económicos de coyuntura > Actividad industrial, base 2018 > Series Originales > Índice de volumen físico > 31-33 Industrias manufactureras > Total industrias manufactureras (Índice base 2018=100) Monthly /f1 | O6: Indicadores económicos de coyuntura > Actividad industrial, base 2018 > Series Originales > Índice de volumen físico > 31-33 Industrias manufactureras > 311 Industria alimentaria > Total subsector 311 (Índice base 2018=100) Monthly /f1 | P6: Indicadores económicos de coyuntura > Actividad industrial, base 2018 > Series Originales > Índice de volumen físico > 31-33 Industrias manufactureras > 312 Industria de las bebidas y del tabaco > Total subsector 312 (Índice base 2018=100) Monthly /f1 | Q6: Indicadores económicos de coyuntura > Actividad industrial, base 2018 > Series Originales > Índice de volumen físico > 31-33 Industrias manufactureras > 313 Fabricación de insumos textiles y acabado de textiles > Total subsector 313 (Índice base 2018=100) Monthly /f1 | R6: Indicadores económicos de coyuntura > Actividad industrial, base 2018 > Series Originales > Índice de volumen físico > 31-33 Industrias manufactureras > 314 Fabricación de productos textiles, excepto prendas de vestir > Total subsector 314 (Índice base 2018=100) Monthly /f1 | S6: Indicadores económicos de coyuntura > Actividad industrial, base 2018 > Series Originales > Índice de volumen físico > 31-33 Industrias manufactureras > 315 Fabricación de prendas de vestir > Total subsector 315 (Índice base 2018=100) Monthly /f1 | T6: Indicadores económicos de coyuntura > Actividad industrial, base 2018 > Series Originales > Índice de volumen físico > 31-33 Industrias manufactureras > 316 Curtido y acabado de cuero y piel, y fabricación de productos de cuero, piel y materiales sucedáneos > Total subsector 316 (Índice base 2018=100) Monthly /f1 | U6: Indicadores económicos de coyuntura > Actividad industrial, base 2018 > Series Originales > Índice de volumen físico > 31-33 Industrias manufactureras > 321 Industria de la madera > Total subsector 321 (Índice base 2018=100) Monthly /f1 | V6: Indicadores económicos de coyuntura > Actividad industrial, base 2018 > Series Originales > Índice de volumen físico > 31-33 Industrias manufactureras > 322 Industria del papel > Total subsector 322 (Índice base 2018=100) Monthly /f1 | W6: Indicadores económicos de coyuntura > Actividad industrial, base 2018 > Series Originales > Índice de volumen físico > 31-33 Industrias manufactureras > 323 Impresión e industrias conexas > Total subsector 323 (Índice base 2018=100) Monthly /f1 | X6: Indicadores económicos de coyuntura > Actividad industrial, base 2018 > Series Originales > Índice de volumen físico > 31-33 Industrias manufactureras > 324 Fabricación de productos derivados del petróleo y del carbón > Total subsector 324 (Índice base 2018=100) Monthly /f1 | Y6: Indicadores económicos de coyuntura > Actividad industrial, base 2018 > Series Originales > Índice de volumen físico > 31-33 Industrias manufactureras > 325 Industria química > Total subsector 325 (Índice base 2018=100) Monthly /f1 | Z6: Indicadores económicos de coyuntura > Actividad industrial, base 2018 > Series Originales > Índice de volumen físico > 31-33 Industrias manufactureras > 326 Industria del plástico y del hule > Total subsector 326 (Índice base 2018=100) Monthly /f1 | AA6: Indicadores económicos de coyuntura > Actividad industrial, base 2018 > Series Originales > Índice de volumen físico > 31-33 Industrias manufactureras > 327 Fabricación de productos a base de minerales no metálicos > Total subsector 327 (Índice base 2018=100) Monthly /f1 | AB6: Indicadores económicos de coyuntura > Actividad industrial, base 2018 > Series Originales > Índice de volumen físico > 31-33 Industrias manufactureras > 331 Industrias metálicas básicas > Total subsector 331 (Índice base 2018=100) Monthly /f1 | AC6: Indicadores económicos de coyuntura > Actividad industrial, base 2018 > Series Originales > Índice de volumen físico > 31-33 Industrias manufactureras > 332 Fabricación de productos metálicos > Total subsector 332 (Índice base 2018=100) Monthly /f1 | AD6: Indicadores económicos de coyuntura > Actividad industrial, base 2018 > Series Originales > Índice de volumen físico > 31-33 Industrias manufactureras > 333 Fabricación de maquinaria y equipo > Total subsector 333 (Índice base 2018=100) Monthly /f1 | AE6: Indicadores económicos de coyuntura > Actividad industrial, base 2018 > Series Originales > Índice de volumen físico > 31-33 Industrias manufactureras > 334 Fabricación de equipo de computación, comunicación, medición y de otros equipos, componentes y accesorios electrónicos > Total subsector 334 (Índice base 2018=100) Monthly /f1 | AF6: Indicadores económicos de coyuntura > Actividad industrial, base 2018 > Series Originales > Índice de volumen físico > 31-33 Industrias manufactureras > 335 Fabricación de accesorios, aparatos eléctricos y equipo de generación de energía eléctrica > Total subsector 335 (Índice base 2018=100) Monthly /f1 | AG6: Indicadores económicos de coyuntura > Actividad industrial, base 2018 > Series Originales > Índice de volumen físico > 31-33 Industrias manufactureras > 336 Fabricación de equipo de transporte > Total subsector 336 (Índice base 2018=100) Monthly /f1 | AH6: Indicadores económicos de coyuntura > Actividad industrial, base 2018 > Series Originales > Índice de volumen físico > 31-33 Industrias manufactureras > 337 Fabricación de muebles, colchones y persianas > Total subsector 337 (Índice base 2018=100) Monthly /f1 | AI6: Indicadores económicos de coyuntura > Actividad industrial, base 2018 > Series Originales > Índice de volumen físico > 31-33 Industrias manufactureras > 339 Otras industrias manufactureras > Total subsector 339 (Índice base 2018=100) Monthly /f1
A7: 1993/01 | B7: 00 Estados Unidos Mexicanos | C7: 63.307782 | D7: 105.63372 | E7: 137.51945 | F7: 51.030422 | G7: 19.03529 | H7: 31.140234 | I7: 31.140234 | J7: 65.066709 | K7: 70.822977 | L7: 47.897351 | M7: 51.564633 | N7: 57.569208 | O7: 57.390254 | P7: 44.153444 | Q7: 94.833067 | R7: 62.183341 | S7: 68.45063 | T7: 145.51019 | U7: 116.59941 | V7: 43.682621 | W7: 51.19384 | X7: 148.67981 | Y7: 74.371783 | Z7: 55.01086 | AA7: 61.979202 | AB7: 64.278668 | AC7: 68.80715 | AD7: 92.173815 | AE7: 63.077464 | AF7: 89.356525 | AG7: 22.932642 | AH7: 102.71802 | AI7: 25.311203
A8: 1993/02 | B8: 00 Estados Unidos Mexicanos | C8: 64.88913 | D8: 97.271624 | E8: 124.34812 | F8: 50.893698 | G8: 23.778913 | H8: 30.534604 | I8: 30.534604 | J8: 72.301502 | K8: 81.527051 | L8: 43.250169 | M8: 52.468069 | N8: 59.595205 | O8: 56.498795 | P8: 44.012904 | Q8: 104.82684 | R8: 68.950249 | S8: 74.73758 | T8: 134.21673 | U8: 149.07586 | V8: 42.906637 | W8: 61.957641 | X8: 136.84145 | Y8: 75.260068 | Z8: 61.863461 | AA8: 61.588003 | AB8: 62.448839 | AC8: 74.174943 | AD8: 76.252788 | AE8: 67.30135 | AF8: 132.28874 | AG8: 25.583303 | AH8: 85.137909 | AI8: 31.087167
A9: 1993/03 | B9: 00 Estados Unidos Mexicanos | C9: 68.070475 | D9: 109.36336 | E9: 138.97018 | F9: 58.169826 | G9: 31.07088 | H9: 30.87515 | I9: 30.87515 | J9: 72.200179 | K9: 79.128218 | L9: 52.883713 | M9: 54.362407 | N9: 62.29373 | O9: 63.501836 | P9: 48.047544 | Q9: 120.93757 | R9: 83.426598 | S9: 92.182461 | T9: 130.05973 | U9: 150.27262 | V9: 48.080186 | W9: 78.512853 | X9: 152.64309 | Y9: 84.862447 | Z9: 63.356535 | AA9: 69.985766 | AB9: 79.890169 | AC9: 74.734566 | AD9: 68.95213 | AE9: 44.941939 | AF9: 102.19225 | AG9: 29.505776 | AH9: 95.998047 | AI9: 43.612944
A10: 1993/04 | B10: 00 Estados Unidos Mexicanos | C10: 64.524614 | D10: 105.54602 | E10: 136.19254 | F10: 52.224819 | G10: 25.920872 | H10: 31.478529 | I10: 31.478529 | J10: 65.190467 | K10: 72.387479 | L10: 43.424498 | M10: 48.661319 | N10: 59.448857 | O10: 58.744075 | P10: 44.859164 | Q10: 94.519973 | R10: 76.133837 | S10: 82.431411 | T10: 119.61867 | U10: 106.7142 | V10: 45.623729 | W10: 48.44936 | X10: 151.07931 | Y10: 72.737881 | Z10: 61.153979 | AA10: 63.875252 | AB10: 75.151028 | AC10: 56.992991 | AD10: 57.119224 | AE10: 84.844837 | AF10: 86.734528 | AG10: 25.439879 | AH10: 84.081552 | AI10: 46.197448
A11: 1993/05 | B11: 00 Estados Unidos Mexicanos | C11: 64.382808 | D11: 108.37189 | E11: 141.07461 | F11: 51.39583 | G11: 23.7365 | H11: 32.421097 | I11: 32.421097 | J11: 65.265742 | K11: 70.539985 | L11: 47.224884 | M11: 55.613344 | N11: 58.564004 | O11: 56.901305 | P11: 52.096605 | Q11: 113.49406 | R11: 78.465527 | S11: 83.241648 | T11: 131.23378 | U11: 99.867458 | V11: 46.510548 | W11: 59.980155 | X11: 145.1001 | Y11: 84.723354 | Z11: 54.93035 | AA11: 70.553806 | AB11: 68.741554 | AC11: 57.673804 | AD11: 103.75202 | AE11: 60.98201 | AF11: 55.468076 | AG11: 25.483181 | AH11: 87.462363 | AI11: 30.722828
A12: 1993/06 | B12: 00 Estados Unidos Mexicanos | C12: 62.471146 | D12: 104.86255 | E12: 136.55268 | F12: 48.681739 | G12: 27.009119 | H12: 32.308556 | I12: 32.308556 | J12: 64.263124 | K12: 68.29113 | L12: 50.337472 | M12: 57.06529 | N12: 56.522282 | O12: 54.479365 | P12: 44.861248 | Q12: 128.20666 | R12: 90.264204 | S12: 86.187053 | T12: 125.88838 | U12: 114.52614 | V12: 44.46658 | W12: 62.491634 | X12: 150.91294 | Y12: 87.218856 | Z12: 50.713867 | AA12: 67.682672 | AB12: 62.6407 | AC12: 63.757022 | AD12: 80.869801 | AE12: 50.623456 | AF12: 80.277759 | AG12: 23.229154 | AH12: 84.240608 | AI12: 30.793396
A13: 1993/07 | B13: 00 Estados Unidos Mexicanos | C13: 64.791953 | D13: 108.4778 | E13: 139.30101 | F13: 53.147382 | G13: 35.702534 | H13: 32.780141 | I13: 32.780141 | J13: 65.932771 | K13: 69.72745 | L13: 56.998255 | M13: 54.224863 | N13: 58.959575 | O13: 54.092809 | P13: 44.997517 | Q13: 107.43628 | R13: 81.384212 | S13: 81.163123 | T13: 128.20263 | U13: 77.156215 | V13: 46.533101 | W13: 72.753131 | X13: 148.23282 | Y13: 78.332105 | Z13: 48.137441 | AA13: 65.989923 | AB13: 66.24088 | AC13: 55.592486 | AD13: 117.43974 | AE13: 84.734295 | AF13: 74.921658 | AG13: 20.990239 | AH13: 94.494641 | AI13: 34.230792
A14: 1993/08 | B14: 00 Estados Unidos Mexicanos | C14: 66.301834 | D14: 107.44436 | E14: 138.94431 | F14: 53.568312 | G14: 21.607658 | H14: 32.121464 | I14: 32.121464 | J14: 73.735953 | K14: 79.685283 | L14: 54.112194 | M14: 61.992936 | N14: 59.283157 | O14: 54.022773 | P14: 42.171006 | Q14: 97.491887 | R14: 95.871069 | S14: 84.921394 | T14: 128.28999 | U14: 82.074308 | V14: 43.521364 | W14: 99.495514 | X14: 159.52989 | Y14: 80.502281 | Z14: 52.799026 | AA14: 65.497135 | AB14: 63.135708 | AC14: 83.855074 | AD14: 82.661925 | AE14: 74.849598 | AF14: 106.5077 | AG14: 20.724113 | AH14: 92.178936 | AI14: 37.246239
A15: 1993/09 | B15: 00 Estados Unidos Mexicanos | C15: 67.703709 | D15: 105.4224 | E15: 136.74228 | F15: 51.065528 | G15: 23.464133 | H15: 32.169525 | I15: 32.169525 | J15: 76.459477 | K15: 80.522312 | L15: 64.86204 | M15: 66.316263 | N15: 61.081424 | O15: 55.097998 | P15: 41.091602 | Q15: 99.243382 | R15: 94.183051 | S15: 84.223276 | T15: 126.19483 | U15: 89.621461 | V15: 43.229357 | W15: 80.736709 | X15: 160.49837 | Y15: 82.278088 | Z15: 55.440858 | AA15: 64.826524 | AB15: 70.422934 | AC15: 67.144042 | AD15: 51.755421 | AE15: 71.920327 | AF15: 179.28168 | AG15: 22.636358 | AH15: 91.307875 | AI15: 42.537639
A16: 1993/10 | B16: 00 Estados Unidos Mexicanos | C16: 66.405456 | D16: 110.53434 | E16: 142.33441 | F16: 55.971487 | G16: 24.624958 | H16: 30.805084 | I16: 30.805084 | J16: 73.707244 | K16: 75.875909 | L16: 75.677492 | M16: 58.684111 | N16: 58.979102 | O16: 55.919523 | P16: 43.460296 | Q16: 111.16329 | R16: 94.695413 | S16: 83.100261 | T16: 144.40548 | U16: 78.975013 | V16: 43.801391 | W16: 78.517026 | X16: 159.04334 | Y16: 86.327758 | Z16: 69.344234 | AA16: 68.118117 | AB16: 69.432957 | AC16: 68.171427 | AD16: 75.367304 | AE16: 47.358398 | AF16: 106.38905 | AG16: 25.621235 | AH16: 66.859023 | AI16: 44.057522
A17: 1993/11 | B17: 00 Estados Unidos Mexicanos | C17: 65.323065 | D17: 107.19305 | E17: 137.67783 | F17: 54.383918 | G17: 26.997568 | H17: 29.53864 | I17: 29.53864 | J17: 72.199083 | K17: 72.181391 | L17: 85.633097 | M17: 56.484827 | N17: 58.480231 | O17: 53.864974 | P17: 46.508783 | Q17: 104.44186 | R17: 66.0694 | S17: 99.34826 | T17: 135.75556 | U17: 78.018508 | V17: 42.093758 | W17: 97.991035 | X17: 150.11475 | Y17: 86.981682 | Z17: 52.020437 | AA17: 64.733273 | AB17: 65.661812 | AC17: 74.363642 | AD17: 56.761817 | AE17: 84.158652 | AF17: 61.25698 | AG17: 25.057148 | AH17: 81.880953 | AI17: 38.668976
A18: 1993/12 | B18: 00 Estados Unidos Mexicanos | C18: 67.828452 | D18: 111.2314 | E18: 142.64912 | F18: 53.492815 | G18: 42.811629 | H18: 28.360196 | I18: 28.360196 | J18: 79.241961 | K18: 80.071807 | L18: 85.913968 | M18: 66.525065 | N18: 59.674666 | O18: 62.389871 | P18: 60.152075 | Q18: 95.296548 | R18: 73.856474 | S18: 73.451446 | T18: 109.31282 | U18: 112.55095 | V18: 38.938847 | W18: 99.534732 | X18: 162.63747 | Y18: 76.032291 | Z18: 52.525657 | AA18: 64.195783 | AB18: 63.391228 | AC18: 50.162514 | AD18: 50.760867 | AE18: 83.841417 | AF18: 96.624942 | AG18: 24.104653 | AH18: 97.084399 | AI18: 27.085022
... A402: 2025/12 | B402: 00 Estados Unidos Mexicanos | C402: 98.432485 | D402: 94.00479 | E402: 92.472017 | F402: 87.327685 | G402: 138.11747 | H402: 64.265474 | I402: 64.265474 | J402: 108.29884 | K402: 105.22091 | L402: 119.61598 | M402: 113.00286 | N402: 99.538255 | O402: 111.41117 | P402: 98.796336 | Q402: 63.736307 | R402: 86.784971 | S402: 60.638927 | T402: 62.282522 | U402: 69.880533 | V402: 91.187641 | W402: 96.077679 | X402: 180.55887 | Y402: 96.472628 | Z402: 89.568721 | AA402: 95.445445 | AB402: 97.70672 | AC402: 82.858984 | AD402: 93.340043 | AE402: 115.12273 | AF402: 109.97241 | AG402: 82.028497 | AH402: 83.293454 | AI402: 132.8345
A407: Sources: /f1 INEGI System of National Accounts of Mexico. Monthly Industrial Activity Indicator (IMAI)

Sheet DES
A1: National Institute of Statistics and Geography (INEGI)
A2: Economic Information Bank
A3: Consult Date: 11/02/2026 06:30:38
A4: Índice base 2018=100
C5: 1 | D5: 21 | E5: 211 | F5: 212 | G5: 213 | H5: 22 | I5: 23 | J5: 236 | K5: 237 | L5: 238 | M5: 31 | N5: 311 | O5: 312 | P5: 313 | Q5: 314 | R5: 315 | S5: 316 | T5: 321 | U5: 322 | V5: 323 | W5: 324 | X5: 325 | Y5: 326 | Z5: 327 | AA5: 331 | AB5: 332 | AC5: 333 | AD5: 334 | AE5: 335 | AF5: 336 | AG5: 337 | AH5: 339
A6: Period | B6: Geographic area | C6: Indicadores económicos de coyuntura > Actividad industrial, base 2018 > Series desestacionalizadas y tendencia-ciclo > Total de la actividad industrial > Serie desestacionalizada > Índice (Índice base 2018=100) Monthly /f1 | D6: Indicadores económicos de coyuntura > Actividad industrial, base 2018 > Series desestacionalizadas y tendencia-ciclo > Minería > Total > Serie desestacionalizada > Índice (Índice base 2018=100) Monthly /f1 | E6: Indicadores económicos de coyuntura > Actividad industrial, base 2018 > Series desestacionalizadas y tendencia-ciclo > Minería > 211 Extracción de petróleo y gas > Serie desestacionalizada > Índice (Índice base 2018=100) Monthly /f1 | F6: Indicadores económicos de coyuntura > Actividad industrial, base 2018 > Series desestacionalizadas y tendencia-ciclo > Minería > 212 Minería de minerales metálicos y no metálicos, excepto petróleo y gas > Serie desestacionalizada > Índice (Índice base 2018=100) Monthly /f1 | G6: Indicadores económicos de coyuntura > Actividad industrial, base 2018 > Series desestacionalizadas y tendencia-ciclo > Minería > 213 Servicios relacionados con la minería > Serie desestacionalizada > Índice (Índice base 2018=100) Monthly /f1 | H6: Indicadores económicos de coyuntura > Actividad industrial, base 2018 > Series desestacionalizadas y tendencia-ciclo > Generación, transmisión y distribución de energía eléctrica, suministro de agua y de gas por ductos al consumidor final > Serie desestacionalizada > Índice (Índice base 2018=100) Monthly /f1 | I6: Indicadores económicos de coyuntura > Actividad industrial, base 2018 > Series desestacionalizadas y tendencia-ciclo > Construcción > Total > Serie desestacionalizada > Índice (Índice base 2018=100) Monthly /f1 | J6: Indicadores económicos de coyuntura > Actividad industrial, base 2018 > Series desestacionalizadas y tendencia-ciclo > Construcción > 236 Edificación > Serie desestacionalizada > Índice (Índice base 2018=100) Monthly /f1 | K6: Indicadores económicos de coyuntura > Actividad industrial, base 2018 > Series desestacionalizadas y tendencia-ciclo > Construcción > 237 Construcción de obras de ingeniería civil > Serie desestacionalizada > Índice (Índice base 2018=100) Monthly /f1 | L6: Indicadores económicos de coyuntura > Actividad industrial, base 2018 > Series desestacionalizadas y tendencia-ciclo > Construcción > 238 Trabajos especializados para la construcción > Serie desestacionalizada > Índice (Índice base 2018=100) Monthly /f1 | M6: Indicadores económicos de coyuntura > Actividad industrial, base 2018 > Series desestacionalizadas y tendencia-ciclo > Industrias manufactureras > Total > Serie desestacionalizada > Índice (Índice base 2018=100) Monthly /f1 | N6: Indicadores económicos de coyuntura > Actividad industrial, base 2018 > Series desestacionalizadas y tendencia-ciclo > Industrias manufactureras > 311 Industria alimentaria > Serie desestacionalizada > Índice (Índice base 2018=100) Monthly /f1 | O6: Indicadores económicos de coyuntura > Actividad industrial, base 2018 > Series desestacionalizadas y tendencia-ciclo > Industrias manufactureras > 312 Industria de las bebidas y del tabaco > Serie desestacionalizada > Índice (Índice base 2018=100) Monthly /f1 | P6: Indicadores económicos de coyuntura > Actividad industrial, base 2018 > Series desestacionalizadas y tendencia-ciclo > Industrias manufactureras > 313 Fabricación de insumos textiles y acabado de textiles > Serie desestacionalizada > Índice (Índice base 2018=100) Monthly /f1 | Q6: Indicadores económicos de coyuntura > Actividad industrial, base 2018 > Series desestacionalizadas y tendencia-ciclo > Industrias manufactureras > 314 Fabricación de productos textiles, excepto prendas de vestir > Serie desestacionalizada > Índice (Índice base 2018=100) Monthly /f1 | R6: Indicadores económicos de coyuntura > Actividad industrial, base 2018 > Series desestacionalizadas y tendencia-ciclo > Industrias manufactureras > 315 Fabricación de prendas de vestir > Serie desestacionalizada > Índice (Índice base 2018=100) Monthly /f1 | S6: Indicadores económicos de coyuntura > Actividad industrial, base 2018 > Series desestacionalizadas y tendencia-ciclo > Industrias manufactureras > 316 Curtido y acabado de cuero y piel, y fabricación de productos de cuero, piel y materiales sucedáneos > Serie desestacionalizada > Índice (Índice base 2018=100) Monthly /f1 | T6: Indicadores económicos de coyuntura > Actividad industrial, base 2018 > Series desestacionalizadas y tendencia-ciclo > Industrias manufactureras > 321 Industria de la madera > Serie desestacionalizada > Índice (Índice base 2018=100) Monthly /f1 | U6: Indicadores económicos de coyuntura > Actividad industrial, base 2018 > Series desestacionalizadas y tendencia-ciclo > Industrias manufactureras > 322 Industria del papel > Serie desestacionalizada > Índice (Índice base 2018=100) Monthly /f1 | V6: Indicadores económicos de coyuntura > Actividad industrial, base 2018 > Series desestacionalizadas y tendencia-ciclo > Industrias manufactureras > 323 Impresión e industrias conexas > Serie desestacionalizada > Índice (Índice base 2018=100) Monthly /f1 | W6: Indicadores económicos de coyuntura > Actividad industrial, base 2018 > Series desestacionalizadas y tendencia-ciclo > Industrias manufactureras > 324 Fabricación de productos derivados del petróleo y del carbón > Serie desestacionalizada > Índice (Índice base 2018=100) Monthly /f1 | X6: Indicadores económicos de coyuntura > Actividad industrial, base 2018 > Series desestacionalizadas y tendencia-ciclo > Industrias manufactureras > 325 Industria química > Serie desestacionalizada > Índice (Índice base 2018=100) Monthly /f1 | Y6: Indicadores económicos de coyuntura > Actividad industrial, base 2018 > Series desestacionalizadas y tendencia-ciclo > Industrias manufactureras > 326 Industria del plástico y del hule > Serie desestacionalizada > Índice (Índice base 2018=100) Monthly /f1 | Z6: Indicadores económicos de coyuntura > Actividad industrial, base 2018 > Series desestacionalizadas y tendencia-ciclo > Industrias manufactureras > 327 Fabricación de productos a base de minerales no metálicos > Serie desestacionalizada > Índice (Índice base 2018=100) Monthly /f1 | AA6: Indicadores económicos de coyuntura > Actividad industrial, base 2018 > Series desestacionalizadas y tendencia-ciclo > Industrias manufactureras > 331 Industrias metálicas básicas > Serie desestacionalizada > Índice (Índice base 2018=100) Monthly /f1 | AB6: Indicadores económicos de coyuntura > Actividad industrial, base 2018 > Series desestacionalizadas y tendencia-ciclo > Industrias manufactureras > 332 Fabricación de productos metálicos > Serie desestacionalizada > Índice (Índice base 2018=100) Monthly /f1 | AC6: Indicadores económicos de coyuntura > Actividad industrial, base 2018 > Series desestacionalizadas y tendencia-ciclo > Industrias manufactureras > 333 Fabricación de maquinaria y equipo > Serie desestacionalizada > Índice (Índice base 2018=100) Monthly /f1 | AD6: Indicadores económicos de coyuntura > Actividad industrial, base 2018 > Series desestacionalizadas y tendencia-ciclo > Industrias manufactureras > 334 Fabricación de equipo de computación, comunicación, medición y de otros equipos, componentes y accesorios electrónicos > Serie desestacionalizada > Índice (Índice base 2018=100) Monthly /f1 | AE6: Indicadores económicos de coyuntura > Actividad industrial, base 2018 > Series desestacionalizadas y tendencia-ciclo > Industrias manufactureras > 335 Fabricación de accesorios, aparatos eléctricos y equipo de generación de energía eléctrica > Serie desestacionalizada > Índice (Índice base 2018=100) Monthly /f1 | AF6: Indicadores económicos de coyuntura > Actividad industrial, base 2018 > Series desestacionalizadas y tendencia-ciclo > Industrias manufactureras > 336 Fabricación de equipo de transporte > Serie desestacionalizada > Índice (Índice base 2018=100) Monthly /f1 | AG6: Indicadores económicos de coyuntura > Actividad industrial, base 2018 > Series desestacionalizadas y tendencia-ciclo > Industrias manufactureras > 337 Fabricación de muebles, colchones y persianas > Serie desestacionalizada > Índice (Índice base 2018=100) Monthly /f1 | AH6: Indicadores económicos de coyuntura > Actividad industrial, base 2018 > Series desestacionalizadas y tendencia-ciclo > Industrias manufactureras > 339 Otras industrias manufactureras > Serie desestacionalizada > Índice (Índice base 2018=100) Monthly /f1
A7: 1993/01 | B7: 00 Estados Unidos Mexicanos | C7: 63.258358 | D7: 103.82622 | E7: 133.98788 | F7: 51.489396 | G7: 26.853425 | H7: 32.320848 | I7: 68.088949 | J7: 73.536636 | K7: 50.695664 | L7: 54.863354 | M7: 56.770225 | N7: 56.703984 | O7: 46.367143 | P7: 103.37887 | Q7: 79.876093 | R7: 84.737293 | S7: 135.25245 | T7: 119.04194 | U7: 43.47159 | V7: 69.440375 | W7: 145.44599 | X7: 78.870629 | Y7: 56.392848 | Z7: 65.276444 | AA7: 67.31468 | AB7: 65.551765 | AC7: 90.914155 | AD7: 50.929734 | AE7: 76.326007 | AF7: 24.459117 | AG7: 88.09005 | AH7: 32.111926
A8: 1993/02 | B8: 00 Estados Unidos Mexicanos | C8: 65.758562 | D8: 104.84717 | E8: 135.25634 | F8: 53.937792 | G8: 25.957369 | H8: 32.337144 | I8: 70.0521 | J8: 74.831957 | K8: 53.963169 | L8: 56.174654 | M8: 59.074068 | N8: 56.205878 | O8: 48.168369 | P8: 106.75584 | Q8: 83.848686 | R8: 84.039591 | S8: 132.41628 | T8: 126.78916 | U8: 45.268591 | V8: 78.615499 | W8: 147.70209 | X8: 81.404803 | Y8: 57.026281 | Z8: 66.913292 | AA8: 64.74265 | AB8: 66.814864 | AC8: 56.644369 | AD8: 62.766522 | AE8: 122.44307 | AF8: 26.951031 | AG8: 90.481976 | AH8: 35.09709
A9: 1993/03 | B9: 00 Estados Unidos Mexicanos | C9: 66.229087 | D9: 106.02707 | E9: 136.23189 | F9: 54.334356 | G9: 26.028702 | H9: 32.150264 | I9: 70.199033 | J9: 75.628759 | K9: 54.426498 | L9: 56.260143 | M9: 59.782496 | N9: 57.073435 | O9: 47.437815 | P9: 111.20004 | Q9: 81.687349 | R9: 86.204351 | S9: 125.93328 | T9: 123.98979 | U9: 45.707607 | V9: 78.049262 | W9: 143.50585 | X9: 82.266502 | Y9: 56.334317 | Z9: 67.54074 | AA9: 70.697057 | AB9: 71.649738 | AC9: 71.652525 | AD9: 61.730662 | AE9: 119.75968 | AF9: 27.760037 | AG9: 95.891966 | AH9: 35.4615
A10: 1993/04 | B10: 00 Estados Unidos Mexicanos | C10: 65.398922 | D10: 106.68759 | E10: 137.68547 | F10: 52.68964 | G10: 25.432842 | H10: 32.248926 | I10: 69.636174 | J10: 75.292197 | K10: 49.489893 | L10: 55.369433 | M10: 59.205421 | N10: 55.58499 | O10: 48.296983 | P10: 107.73771 | Q10: 81.148092 | R10: 83.469792 | S10: 130.29656 | T10: 109.30633 | U10: 45.681707 | V10: 76.21839 | W10: 148.43477 | X10: 76.011842 | Y10: 55.706492 | Z10: 67.331308 | AA10: 70.307222 | AB10: 63.448344 | AC10: 69.905145 | AD10: 86.210979 | AE10: 80.430558 | AF10: 25.902592 | AG10: 92.365691 | AH10: 44.098705
A11: 1993/05 | B11: 00 Estados Unidos Mexicanos | C11: 65.40354 | D11: 106.17943 | E11: 137.81951 | F11: 50.584375 | G11: 25.199341 | H11: 32.138633 | I11: 70.683159 | J11: 76.049184 | K11: 55.249562 | L11: 59.105224 | M11: 58.827093 | N11: 58.847061 | O11: 48.584005 | P11: 115.94488 | Q11: 84.308727 | R11: 83.447229 | S11: 128.46125 | T11: 104.60271 | U11: 46.121808 | V11: 66.418693 | W11: 142.43193 | X11: 81.760955 | Y11: 55.929058 | Z11: 66.560832 | AA11: 69.529917 | AB11: 65.186033 | AC11: 78.502163 | AD11: 70.376315 | AE11: 77.904445 | AF11: 25.821934 | AG11: 90.447137 | AH11: 31.885312
A12: 1993/06 | B12: 00 Estados Unidos Mexicanos | C12: 64.893455 | D12: 107.04495 | E12: 137.95456 | F12: 53.0955 | G12: 26.00139 | H12: 31.676705 | I12: 69.190741 | J12: 74.934151 | K12: 54.089684 | L12: 57.285303 | M12: 58.518355 | N12: 56.620087 | O12: 42.06737 | P12: 117.01418 | Q12: 86.709826 | R12: 82.966446 | S12: 126.46031 | T12: 100.29028 | U12: 43.446218 | V12: 73.834686 | W12: 153.64047 | X12: 81.321962 | Y12: 54.126756 | Z12: 64.560076 | AA12: 66.968762 | AB12: 65.536083 | AC12: 65.880379 | AD12: 76.093217 | AE12: 103.75236 | AF12: 23.610037 | AG12: 91.036887 | AH12: 33.041046
A13: 1993/07 | B13: 00 Estados Unidos Mexicanos | C13: 65.489211 | D13: 106.838 | E13: 137.35711 | F13: 53.489839 | G13: 26.580161 | H13: 31.381134 | I13: 68.760973 | J13: 74.426951 | K13: 56.228665 | L13: 56.653396 | M13: 59.744527 | N13: 56.378802 | O13: 42.093765 | P13: 106.33831 | Q13: 83.113444 | R13: 82.943533 | S13: 130.54317 | T13: 97.183752 | U13: 44.974179 | V13: 73.019796 | W13: 148.21219 | X13: 80.118589 | Y13: 54.182054 | Z13: 64.942395 | AA13: 67.435131 | AB13: 61.327277 | AC13: 84.541804 | AD13: 82.46683 | AE13: 98.024086 | AF13: 23.37322 | AG13: 88.137556 | AH13: 35.433375
A14: 1993/08 | B14: 00 Estados Unidos Mexicanos | C14: 65.633418 | D14: 106.83507 | E14: 137.56214 | F14: 52.89803 | G14: 27.101827 | H14: 30.92046 | I14: 69.534725 | J14: 73.930643 | K14: 57.872776 | L14: 56.702218 | M14: 59.969986 | N14: 56.776316 | O14: 40.980911 | P14: 94.831613 | Q14: 81.968879 | R14: 83.368922 | S14: 127.2738 | T14: 92.807652 | U14: 43.758806 | V14: 77.210494 | W14: 157.87858 | X14: 80.208572 | Y14: 51.200727 | Z14: 64.325209 | AA14: 63.445714 | AB14: 71.558441 | AC14: 90.210222 | AD14: 79.273957 | AE14: 119.98672 | AF14: 21.515864 | AG14: 94.848785 | AH14: 34.935907
A15: 1993/09 | B15: 00 Estados Unidos Mexicanos | C15: 65.517753 | D15: 107.59489 | E15: 138.99262 | F15: 52.400298 | G15: 27.654209 | H15: 30.768533 | I15: 70.541332 | J15: 74.24628 | K15: 62.523181 | L15: 57.665384 | M15: 59.626323 | N15: 57.722276 | O15: 43.32953 | P15: 101.25409 | Q15: 77.03426 | R15: 83.191442 | S15: 123.83594 | T15: 93.144132 | U15: 43.108199 | V15: 75.473077 | W15: 163.73501 | X15: 80.739956 | Y15: 56.270968 | Z15: 65.142347 | AA15: 70.177673 | AB15: 66.754453 | AC15: 70.396918 | AD15: 68.75008 | AE15: 105.06712 | AF15: 22.877435 | AG15: 84.910475 | AH15: 38.371107
A16: 1993/10 | B16: 00 Estados Unidos Mexicanos | C16: 65.771155 | D16: 108.63783 | E16: 140.06017 | F16: 53.293766 | G16: 28.386792 | H16: 30.116253 | I16: 70.80656 | J16: 74.736453 | K16: 63.832638 | L16: 57.127706 | M16: 59.908257 | N16: 57.261687 | O16: 43.659865 | P16: 103.63326 | Q16: 86.602784 | R16: 79.74737 | S16: 141.05548 | T16: 78.680098 | U16: 43.427987 | V16: 74.708206 | W16: 164.62414 | X16: 81.676271 | Y16: 64.754146 | Z16: 65.796731 | AA16: 65.74661 | AB16: 65.891363 | AC16: 94.868949 | AD16: 62.056448 | AE16: 90.250274 | AF16: 22.96326 | AG16: 79.561366 | AH16: 38.031979
A17: 1993/11 | B17: 00 Estados Unidos Mexicanos | C17: 65.804517 | D17: 108.89229 | E17: 140.26352 | F17: 52.937215 | G17: 29.741853 | H17: 29.536007 | I17: 72.75887 | J17: 76.444641 | K17: 68.274855 | L17: 57.592758 | M17: 59.304624 | N17: 56.096628 | O17: 45.793124 | P17: 100.36117 | Q17: 65.692678 | R17: 80.833556 | S17: 128.38496 | T17: 86.009347 | U17: 42.369152 | V17: 72.61383 | W17: 154.66763 | X17: 83.297597 | Y17: 55.112115 | Z17: 65.877428 | AA17: 66.776232 | AB17: 67.053677 | AC17: 70.760476 | AD17: 68.280799 | AE17: 65.818422 | AF17: 22.735971 | AG17: 83.223748 | AH17: 36.801959
A18: 1993/12 | B18: 00 Estados Unidos Mexicanos | C18: 66.835246 | D18: 108.89108 | E18: 140.30426 | F18: 53.494784 | G18: 30.392116 | H18: 29.099987 | I18: 74.806207 | J18: 76.734813 | K18: 71.999821 | L18: 58.310166 | M18: 59.916383 | N18: 57.577982 | O18: 61.118135 | P18: 101.29791 | Q18: 73.939494 | R18: 77.912553 | S18: 128.00718 | T18: 110.68268 | U18: 41.879359 | V18: 74.334797 | W18: 156.11242 | X18: 81.561771 | Y18: 59.679324 | Z18: 64.783285 | AA18: 67.630954 | AB18: 60.484831 | AC18: 76.131756 | AD18: 58.469036 | AE18: 99.530018 | AF18: 23.465306 | AG18: 84.25523 | AH18: 34.283704
... A402: 2025/12 | B402: 00 Estados Unidos Mexicanos | C402: 101.74616 | D402: 89.774476 | E402: 91.269139 | F402: 86.843647 | G402: 89.206836 | H402: 68.909502 | I402: 106.25873 | J402: 107.12448 | K402: 106.83097 | L402: 101.60757 | M402: 105.92103 | N402: 107.59213 | O402: 103.02013 | P402: 75.974681 | Q402: 89.694382 | R402: 66.535322 | S402: 71.487163 | T402: 81.020015 | U402: 96.573709 | V402: 92.334802 | W402: 177.05302 | X402: 99.261745 | Y402: 103.17935 | Z402: 97.131578 | AA402: 98.395798 | AB402: 91.017649 | AC402: 103.21247 | AD402: 122.95658 | AE402: 118.35455 | AF402: 99.002141 | AG402: 82.504284 | AH402: 132.75573
A407: Sources: /f1 INEGI. Series calculadas por métodos econométricos a partir de las cifras generadas por el Sistema de Cuentas Nacionales de México.

Sheet TEND
A1: National Institute of Statistics and Geography (INEGI)
A2: Economic Information Bank
A3: Consult Date: 11/02/2026 06:31:01
A4: Índice base 2018=100
C5: 1 | D5: 21 | E5: 211 | F5: 212 | G5: 213 | H5: 22 | I5: 23 | J5: 236 | K5: 237 | L5: 238 | M5: 31 | N5: 311 | O5: 312 | P5: 313 | Q5: 314 | R5: 315 | S5: 316 | T5: 321 | U5: 322 | V5: 323 | W5: 324 | X5: 325 | Y5: 326 | Z5: 327 | AA5: 331 | AB5: 332 | AC5: 333 | AD5: 334 | AE5: 335 | AF5: 336 | AG5: 337 | AH5: 339
A6: Period | B6: Geographic area | C6: Indicadores económicos de coyuntura > Actividad industrial, base 2018 > Series desestacionalizadas y tendencia-ciclo > Total de la actividad industrial > Tendencia-ciclo > Índice (Índice base 2018=100) Monthly /f1 | D6: Indicadores económicos de coyuntura > Actividad industrial, base 2018 > Series desestacionalizadas y tendencia-ciclo > Minería > Total > Tendencia-ciclo > Índice (Índice base 2018=100) Monthly /f1 | E6: Indicadores económicos de coyuntura > Actividad industrial, base 2018 > Series desestacionalizadas y tendencia-ciclo > Minería > 211 Extracción de petróleo y gas > Tendencia-ciclo > Índice (Índice base 2018=100) Monthly /f1 | F6: Indicadores económicos de coyuntura > Actividad industrial, base 2018 > Series desestacionalizadas y tendencia-ciclo > Minería > 212 Minería de minerales metálicos y no metálicos, excepto petróleo y gas > Tendencia-ciclo > Índice (Índice base 2018=100) Monthly /f1 | G6: Indicadores económicos de coyuntura > Actividad industrial, base 2018 > Series desestacionalizadas y tendencia-ciclo > Minería > 213 Servicios relacionados con la minería > Tendencia-ciclo > Índice (Índice base 2018=100) Monthly /f1 | H6: Indicadores económicos de coyuntura > Actividad industrial, base 2018 > Series desestacionalizadas y tendencia-ciclo > Generación, transmisión y distribución de energía eléctrica, suministro de agua y de gas por ductos al consumidor final > Tendencia-ciclo > Índice (Índice base 2018=100) Monthly /f1 | I6: Indicadores económicos de coyuntura > Actividad industrial, base 2018 > Series desestacionalizadas y tendencia-ciclo > Construcción > Total > Tendencia-ciclo > Índice (Índice base 2018=100) Monthly /f1 | J6: Indicadores económicos de coyuntura > Actividad industrial, base 2018 > Series desestacionalizadas y tendencia-ciclo > Construcción > 236 Edificación > Tendencia-ciclo > Índice (Índice base 2018=100) Monthly /f1 | K6: Indicadores económicos de coyuntura > Actividad industrial, base 2018 > Series desestacionalizadas y tendencia-ciclo > Construcción > 237 Construcción de obras de ingeniería civil > Tendencia-ciclo > Índice (Índice base 2018=100) Monthly /f1 | L6: Indicadores económicos de coyuntura > Actividad industrial, base 2018 > Series desestacionalizadas y tendencia-ciclo > Construcción > 238 Trabajos especializados para la construcción > Tendencia-ciclo > Índice (Índice base 2018=100) Monthly /f1 | M6: Indicadores económicos de coyuntura > Actividad industrial, base 2018 > Series desestacionalizadas y tendencia-ciclo > Industrias manufactureras > Total > Tendencia-ciclo > Índice (Índice base 2018=100) Monthly /f1 | N6: Indicadores económicos de coyuntura > Actividad industrial, base 2018 > Series desestacionalizadas y tendencia-ciclo > Industrias manufactureras > 311 Industria alimentaria > Tendencia-ciclo > Índice (Índice base 2018=100) Monthly /f1 | O6: Indicadores económicos de coyuntura > Actividad industrial, base 2018 > Series desestacionalizadas y tendencia-ciclo > Industrias manufactureras > 312 Industria de las bebidas y del tabaco > Tendencia-ciclo > Índice (Índice base 2018=100) Monthly /f1 | P6: Indicadores económicos de coyuntura > Actividad industrial, base 2018 > Series desestacionalizadas y tendencia-ciclo > Industrias manufactureras > 313 Fabricación de insumos textiles y acabado de textiles > Tendencia-ciclo > Índice (Índice base 2018=100) Monthly /f1 | Q6: Indicadores económicos de coyuntura > Actividad industrial, base 2018 > Series desestacionalizadas y tendencia-ciclo > Industrias manufactureras > 314 Fabricación de productos textiles, excepto prendas de vestir > Tendencia-ciclo > Índice (Índice base 2018=100) Monthly /f1 | R6: Indicadores económicos de coyuntura > Actividad industrial, base 2018 > Series desestacionalizadas y tendencia-ciclo > Industrias manufactureras > 315 Fabricación de prendas de vestir > Tendencia-ciclo > Índice (Índice base 2018=100) Monthly /f1 | S6: Indicadores económicos de coyuntura > Actividad industrial, base 2018 > Series desestacionalizadas y tendencia-ciclo > Industrias manufactureras > 316 Curtido y acabado de cuero y piel, y fabricación de productos de cuero, piel y materiales sucedáneos > Tendencia-ciclo > Índice (Índice base 2018=100) Monthly /f1 | T6: Indicadores económicos de coyuntura > Actividad industrial, base 2018 > Series desestacionalizadas y tendencia-ciclo > Industrias manufactureras > 321 Industria de la madera > Tendencia-ciclo > Índice (Índice base 2018=100) Monthly /f1 | U6: Indicadores económicos de coyuntura > Actividad industrial, base 2018 > Series desestacionalizadas y tendencia-ciclo > Industrias manufactureras > 322 Industria del papel > Tendencia-ciclo > Índice (Índice base 2018=100) Monthly /f1 | V6: Indicadores económicos de coyuntura > Actividad industrial, base 2018 > Series desestacionalizadas y tendencia-ciclo > Industrias manufactureras > 323 Impresión e industrias conexas > Tendencia-ciclo > Índice (Índice base 2018=100) Monthly /f1 | W6: Indicadores económicos de coyuntura > Actividad industrial, base 2018 > Series desestacionalizadas y tendencia-ciclo > Industrias manufactureras > 324 Fabricación de productos derivados del petróleo y del carbón > Tendencia-ciclo > Índice (Índice base 2018=100) Monthly /f1 | X6: Indicadores económicos de coyuntura > Actividad industrial, base 2018 > Series desestacionalizadas y tendencia-ciclo > Industrias manufactureras > 325 Industria química > Tendencia-ciclo > Índice (Índice base 2018=100) Monthly /f1 | Y6: Indicadores económicos de coyuntura > Actividad industrial, base 2018 > Series desestacionalizadas y tendencia-ciclo > Industrias manufactureras > 326 Industria del plástico y del hule > Tendencia-ciclo > Índice (Índice base 2018=100) Monthly /f1 | Z6: Indicadores económicos de coyuntura > Actividad industrial, base 2018 > Series desestacionalizadas y tendencia-ciclo > Industrias manufactureras > 327 Fabricación de productos a base de minerales no metálicos > Tendencia-ciclo > Índice (Índice base 2018=100) Monthly /f1 | AA6: Indicadores económicos de coyuntura > Actividad industrial, base 2018 > Series desestacionalizadas y tendencia-ciclo > Industrias manufactureras > 331 Industrias metálicas básicas > Tendencia-ciclo > Índice (Índice base 2018=100) Monthly /f1 | AB6: Indicadores económicos de coyuntura > Actividad industrial, base 2018 > Series desestacionalizadas y tendencia-ciclo > Industrias manufactureras > 332 Fabricación de productos metálicos > Tendencia-ciclo > Índice (Índice base 2018=100) Monthly /f1 | AC6: Indicadores económicos de coyuntura > Actividad industrial, base 2018 > Series desestacionalizadas y tendencia-ciclo > Industrias manufactureras > 333 Fabricación de maquinaria y equipo > Tendencia-ciclo > Índice (Índice base 2018=100) Monthly /f1 | AD6: Indicadores económicos de coyuntura > Actividad industrial, base 2018 > Series desestacionalizadas y tendencia-ciclo > Industrias manufactureras > 334 Fabricación de equipo de computación, comunicación, medición y de otros equipos, componentes y accesorios electrónicos > Tendencia-ciclo > Índice (Índice base 2018=100) Monthly /f1 | AE6: Indicadores económicos de coyuntura > Actividad industrial, base 2018 > Series desestacionalizadas y tendencia-ciclo > Industrias manufactureras > 335 Fabricación de accesorios, aparatos eléctricos y equipo de generación de energía eléctrica > Tendencia-ciclo > Índice (Índice base 2018=100) Monthly /f1 | AF6: Indicadores económicos de coyuntura > Actividad industrial, base 2018 > Series desestacionalizadas y tendencia-ciclo > Industrias manufactureras > 336 Fabricación de equipo de transporte > Tendencia-ciclo > Índice (Índice base 2018=100) Monthly /f1 | AG6: Indicadores económicos de coyuntura > Actividad industrial, base 2018 > Series desestacionalizadas y tendencia-ciclo > Industrias manufactureras > 337 Fabricación de muebles, colchones y persianas > Tendencia-ciclo > Índice (Índice base 2018=100) Monthly /f1 | AH6: Indicadores económicos de coyuntura > Actividad industrial, base 2018 > Series desestacionalizadas y tendencia-ciclo > Industrias manufactureras > 339 Otras industrias manufactureras > Tendencia-ciclo > Índice (Índice base 2018=100) Monthly /f1
A7: 1993/01 | B7: 00 Estados Unidos Mexicanos | C7: 65.756991 | D7: 104.63085 | E7: 134.93206 | F7: 52.903719 | G7: 26.220422 | H7: 32.397947 | I7: 69.387618 | J7: 74.581817 | K7: 52.582665 | L7: 55.473533 | M7: 58.260104 | N7: 56.654914 | O7: 47.372052 | P7: 106.48298 | Q7: 81.231896 | R7: 84.949084 | S7: 132.24621 | T7: 124.3657 | U7: 45.47737 | V7: 76.371205 | W7: 145.36099 | X7: 80.673345 | Y7: 56.849254 | Z7: 66.740625 | AA7: 69.005051 | AB7: 65.996943 | AC7: 68.947095 | AD7: 56.071316 | AE7: 102.44352 | AF7: 27.599365 | AG7: 90.209709 | AH7: 33.178354
A8: 1993/02 | B8: 00 Estados Unidos Mexicanos | C8: 65.705704 | D8: 105.13135 | E8: 135.60364 | F8: 52.929747 | G8: 26.000696 | H8: 32.350132 | I8: 69.589799 | J8: 74.904586 | K8: 53.13753 | L8: 55.885134 | M8: 58.548941 | N8: 56.671017 | O8: 47.687358 | P8: 107.85074 | Q8: 81.870898 | R8: 84.70636 | S8: 131.15721 | T8: 121.24941 | U8: 45.57307 | V8: 76.175515 | W8: 145.27003 | X8: 81.042988 | Y8: 56.656365 | Z8: 66.842873 | AA8: 69.323204 | AB8: 65.858953 | AC8: 70.006162 | AD8: 59.872625 | AE8: 102.54466 | AF8: 27.292332 | AG8: 90.677609 | AH8: 33.480669
A9: 1993/03 | B9: 00 Estados Unidos Mexicanos | C9: 65.63835 | D9: 105.63842 | E9: 136.28316 | F9: 52.892478 | G9: 25.829723 | H9: 32.253911 | I9: 69.744376 | J9: 75.151428 | K9: 53.712345 | L9: 56.304526 | M9: 58.828353 | N9: 56.678247 | O9: 47.935427 | P9: 109.04297 | Q9: 82.552535 | R9: 84.408536 | S9: 130.07861 | T9: 117.00883 | U9: 45.599363 | V9: 76.042844 | W9: 145.61992 | X9: 81.319109 | Y9: 56.238135 | Z9: 66.787856 | AA9: 69.423955 | AB9: 65.741308 | AC9: 71.702521 | AD9: 64.217345 | AE9: 102.63027 | AF9: 26.739104 | AG9: 91.035268 | AH9: 33.803261
A10: 1993/04 | B10: 00 Estados Unidos Mexicanos | C10: 65.542696 | D10: 106.10935 | E10: 136.9103 | F10: 52.804292 | G10: 25.731877 | H10: 32.12268 | I10: 69.801213 | J10: 75.289581 | K10: 54.266595 | L10: 56.713259 | M10: 59.041708 | N10: 56.678172 | O10: 48.085055 | P10: 109.86103 | Q10: 83.218556 | R10: 84.073157 | S10: 129.13469 | T10: 111.97958 | U10: 45.558351 | V10: 75.830201 | W10: 146.30358 | X10: 81.444341 | Y10: 55.728338 | Z10: 66.552854 | AA10: 69.296195 | AB10: 65.654779 | AC10: 73.840582 | AD10: 68.776565 | AE10: 102.58353 | AF10: 26.018115 | AG10: 91.140587 | AH10: 34.075484
A11: 1993/05 | B11: 00 Estados Unidos Mexicanos | C11: 65.440779 | D11: 106.47657 | E11: 137.38256 | F11: 52.704098 | G11: 25.762653 | H11: 31.950498 | I11: 69.71924 | J11: 75.225315 | K11: 54.791474 | L11: 57.033175 | M11: 59.199553 | N11: 56.67994 | O11: 48.017342 | P11: 109.95192 | Q11: 83.666702 | R11: 83.763684 | S11: 128.37739 | T11: 106.55235 | U11: 45.403084 | V11: 75.606392 | W11: 147.69212 | X11: 81.331801 | Y11: 55.139293 | Z11: 66.106942 | AA11: 68.851363 | AB11: 65.658063 | AC11: 76.462295 | AD11: 73.108796 | AE11: 102.44598 | AF11: 25.11764 | AG11: 90.87197 | AH11: 34.405142
A12: 1993/06 | B12: 00 Estados Unidos Mexicanos | C12: 65.355671 | D12: 106.75503 | E12: 137.71953 | F12: 52.638769 | G12: 26.009048 | H12: 31.721557 | I12: 69.530627 | J12: 74.942137 | K12: 55.47311 | L12: 57.20038 | M12: 59.32227 | N12: 56.714598 | O12: 47.632156 | P12: 109.07852 | Q12: 83.679388 | R12: 83.474533 | S12: 127.81577 | T12: 101.29377 | U12: 45.095782 | V12: 75.354437 | W12: 150.29262 | X12: 81.052357 | Y12: 54.567945 | Z12: 65.575635 | AA12: 68.084098 | AB12: 65.777593 | AC12: 79.020422 | AD12: 76.076273 | AE12: 102.33136 | AF12: 24.141014 | AG12: 90.09166 | AH12: 34.752636
A13: 1993/07 | B13: 00 Estados Unidos Mexicanos | C13: 65.317875 | D13: 107.04399 | E13: 138.0423 | F13: 52.660516 | G13: 26.516834 | H13: 31.412448 | I13: 69.413572 | J13: 74.58752 | K13: 56.539861 | L13: 57.190785 | M13: 59.42363 | N13: 56.808558 | O13: 47.024482 | P13: 107.2438 | Q13: 83.153033 | R13: 83.11075 | S13: 127.39648 | T13: 96.702419 | U13: 44.592348 | V13: 75.089343 | W13: 153.58763 | X13: 80.836455 | Y13: 54.215602 | Z13: 65.107005 | AA13: 67.206818 | AB13: 65.997401 | AC13: 80.636445 | AD13: 76.579544 | AE13: 102.14566 | AF13: 23.265939 | AG13: 88.740021 | AH13: 35.042683
A14: 1993/08 | B14: 00 Estados Unidos Mexicanos | C14: 65.394115 | D14: 107.43148 | E14: 138.45649 | F14: 52.827667 | G14: 27.183193 | H14: 31.022642 | I14: 69.592892 | J14: 74.354052 | K14: 58.281804 | L14: 57.073536 | M14: 59.567602 | N14: 56.967887 | O14: 46.435415 | P14: 104.98999 | Q14: 81.991747 | R14: 82.548863 | S14: 127.20925 | T14: 93.520856 | U14: 43.960982 | V14: 74.784934 | W14: 156.77797 | X14: 80.864935 | Y14: 54.307535 | Z14: 64.852394 | AA14: 66.531111 | AB14: 66.233113 | AC14: 80.84048 | AD14: 74.731392 | AE14: 101.94377 | AF14: 22.684113 | AG14: 87.118516 | AH14: 35.306647
A15: 1993/09 | B15: 00 Estados Unidos Mexicanos | C15: 65.588099 | D15: 107.88731 | E15: 139.00676 | F15: 53.01999 | G15: 27.785265 | H15: 30.573337 | I15: 70.195457 | J15: 74.424159 | K15: 60.852867 | L15: 57.023315 | M15: 59.735406 | N15: 57.152368 | O15: 46.054914 | P15: 103.08087 | Q15: 80.441005 | R15: 81.78806 | S15: 127.18055 | T15: 91.79903 | U15: 43.374019 | V15: 74.481951 | W15: 159.01739 | X15: 81.130137 | Y15: 54.788672 | Z15: 64.895076 | AA15: 66.214928 | AB15: 66.389232 | AC15: 79.661134 | AD15: 71.52072 | AE15: 101.95974 | AF15: 22.483821 | AG15: 85.736 | AH15: 35.573404
A16: 1993/10 | B16: 00 Estados Unidos Mexicanos | C16: 65.860028 | D16: 108.25626 | E16: 139.54198 | F16: 53.068354 | G16: 28.167784 | H16: 30.084022 | I16: 71.26152 | J16: 74.918557 | K16: 64.366379 | L16: 57.218488 | M16: 59.775394 | N16: 57.291531 | O16: 45.917096 | P16: 101.83564 | Q16: 78.732006 | R16: 80.861883 | S16: 127.42488 | T16: 91.019807 | U16: 42.955717 | V16: 74.198711 | W16: 159.75002 | X16: 81.427869 | Y16: 55.548296 | Z16: 65.193027 | AA16: 66.239957 | AB16: 66.419329 | AC16: 77.476846 | AD16: 67.938779 | AE16: 102.03384 | AF16: 22.608743 | AG16: 84.868766 | AH16: 35.837782
A17: 1993/11 | B17: 00 Estados Unidos Mexicanos | C17: 66.177767 | D17: 108.37238 | E17: 139.86588 | F17: 52.906945 | G17: 28.227043 | H17: 29.591122 | I17: 72.868791 | J17: 75.921881 | K17: 69.011373 | L17: 57.885248 | M17: 59.647097 | N17: 57.310977 | O17: 46.027802 | P17: 101.45446 | Q17: 77.418949 | R17: 79.995979 | S17: 127.99589 | T17: 91.170518 | U17: 42.80719 | V17: 73.981748 | W17: 159.26887 | X17: 81.632176 | Y17: 56.487641 | Z17: 65.606861 | AA17: 66.518415 | AB17: 66.488065 | AC17: 74.911379 | AD17: 65.333825 | AE17: 101.8987 | AF17: 22.967089 | AG17: 84.627636 | AH17: 36.081622
A18: 1993/12 | B18: 00 Estados Unidos Mexicanos | C18: 66.54619 | D18: 108.19956 | E18: 139.82825 | F18: 52.711179 | G18: 28.005271 | H18: 29.12045 | I18: 74.959281 | J18: 77.422675 | K18: 74.645813 | L18: 59.057013 | M18: 59.433665 | N18: 57.201692 | O18: 46.273379 | P18: 101.98846 | Q18: 76.902679 | R18: 79.591953 | S18: 128.6127 | T18: 92.190174 | U18: 42.986755 | V18: 73.856295 | W18: 158.33082 | X18: 81.720699 | Y18: 57.503004 | Z18: 66.050553 | AA18: 66.923233 | AB18: 66.754657 | AC18: 72.740422 | AD18: 64.519554 | AE18: 101.50822 | AF18: 23.452417 | AG18: 84.965717 | AH18: 36.293958
... A402: 2025/12 | B402: 00 Estados Unidos Mexicanos | C402: 101.54513 | D402: 89.790208 | E402: 90.635945 | F402: 86.67163 | G402: 88.508486 | H402: 68.767486 | I402: 105.16105 | J402: 106.5228 | K402: 104.05253 | L402: 102.67528 | M402: 105.86105 | N402: 109.37866 | O402: 103.67492 | P402: 76.698945 | Q402: 90.013707 | R402: 67.193994 | S402: 72.777783 | T402: 80.028357 | U402: 97.060952 | V402: 93.140298 | W402: 173.48648 | X402: 100.08155 | Y402: 104.47466 | Z402: 97.008014 | AA402: 97.39361 | AB402: 91.550114 | AC402: 102.11868 | AD402: 122.31831 | AE402: 119.31057 | AF402: 98.336803 | AG402: 82.626921 | AH402: 135.91102
A407: Sources: /f1 INEGI. Series calculadas por métodos econométricos a partir de las cifras generadas por el Sistema de Cuentas Nacionales de México.

Sheet PIB18
B1: ACTIVIDAD INDUSTRIAL | C1: Industria Minera | D1: Extracción de petróleo y gas | E1: Minería de minerales metálicos y no metálicos excepto petróleo y gas, y servicios relacionados | F1: Servicios relacionados con la minería | G1: Electricidad, agua y suministro de gas por ductos al consumidor fina | H1: Generación, transmisión y suministro de energía eléctrica | I1: Construcción | J1: Edificación | K1: Construcción de obras de ingeniería civil u obra pesada | L1: Trabajos especializados para la construcción | M1: Total industrias manufactureras | N1: Industria alimentaria | O1: Industria de las bebidas y del tabaco | P1: Fabricación de insumos textiles | Q1: Confección de productos textiles, excepto prendas de vestir | R1: Fabricación de prendas de vestir | S1: Fabricación de productos de cuero, piel y materiales sucedáneos, excepto prendas de vestir | T1: Industria de la madera | U1: Industria del papel | V1: Impresión e industrias conexas | W1: Fabricación de productos derivados del petróleo y del carbón | X1: Industria química | Y1: Industria del plástico y del hule | Z1: Fabricación de productos a base de minerales no metálicos | AA1: Industrias metálicas básicas | AB1: Fabricación de productos metálicos | AC1: Fabricación de maquinaria y equipo | AD1: Fabricación de equipo de computación, comunicación, medición y otros equipos, componentes y accesorios electrónicos | AE1: Fabricación de equipo de generación eléctrica y aparatos y accesorios eléctricos | AF1: Fabricación de equipo de transporte | AG1: Fabricación de muebles y productos relacionados | AH1: Otras industrias manufactureras
